[2025-06-02 08:23:32,975: INFO : main : logging]
[2025-06-02 08:32:43,795: INFO : main : logging]
[2025-06-08 11:00:35,597: INFO : main : logging]
[2025-06-14 10:36:56,598: ERROR : main : name 'STAGE_NAME' is not defined]
Traceback (most recent call last):
  File "/home/moses/Documents/machine_learning/End_to_end_ml_project/main.py", line 7, in <module>
    logger.info(f">> stage {STAGE_NAME} has started >>>>")
                            ^^^^^^^^^^
NameError: name 'STAGE_NAME' is not defined
[2025-06-14 10:37:46,559: INFO : main : >> stage Data Ingestion stage has started >>>>]
[2025-06-14 10:37:46,561: INFO : common : YML file: config/config.yaml loaded successfully]
[2025-06-14 10:37:46,589: INFO : common : YML file: params.yaml loaded successfully]
[2025-06-14 10:37:46,599: INFO : common : YML file: schema.yaml loaded successfully]
[2025-06-14 10:37:46,600: ERROR : main : "'ConfigBox' object has no attribute 'artifacts_root_'"]
Traceback (most recent call last):
  File "/home/moses/anaconda3/lib/python3.11/site-packages/box/box.py", line 503, in __getitem__
    return super().__getitem__(item)
           ^^^^^^^^^^^^^^^^^^^^^^^^^
KeyError: 'artifacts_root_'

The above exception was the direct cause of the following exception:

Traceback (most recent call last):
  File "/home/moses/anaconda3/lib/python3.11/site-packages/box/box.py", line 536, in __getattr__
    value = self.__getitem__(item, _ignore_default=True)
            ^^^^^^^^^^^^^^^^^^^^^^^^^^^^^^^^^^^^^^^^^^^^
  File "/home/moses/anaconda3/lib/python3.11/site-packages/box/box.py", line 524, in __getitem__
    raise BoxKeyError(str(err)) from _exception_cause(err)
box.exceptions.BoxKeyError: "'artifacts_root_'"

During handling of the above exception, another exception occurred:

Traceback (most recent call last):
  File "/home/moses/anaconda3/lib/python3.11/site-packages/box/box.py", line 538, in __getattr__
    value = object.__getattribute__(self, item)
            ^^^^^^^^^^^^^^^^^^^^^^^^^^^^^^^^^^^
AttributeError: 'ConfigBox' object has no attribute 'artifacts_root_'

The above exception was the direct cause of the following exception:

Traceback (most recent call last):
  File "/home/moses/anaconda3/lib/python3.11/site-packages/box/config_box.py", line 28, in __getattr__
    return super().__getattr__(item)
           ^^^^^^^^^^^^^^^^^^^^^^^^^
  File "/home/moses/anaconda3/lib/python3.11/site-packages/box/box.py", line 552, in __getattr__
    raise BoxKeyError(str(err)) from _exception_cause(err)
box.exceptions.BoxKeyError: "'ConfigBox' object has no attribute 'artifacts_root_'"

During handling of the above exception, another exception occurred:

Traceback (most recent call last):
  File "/home/moses/anaconda3/lib/python3.11/site-packages/box/box.py", line 503, in __getitem__
    return super().__getitem__(item)
           ^^^^^^^^^^^^^^^^^^^^^^^^^
KeyError: 'artifacts_root_'

The above exception was the direct cause of the following exception:

Traceback (most recent call last):
  File "/home/moses/anaconda3/lib/python3.11/site-packages/box/box.py", line 536, in __getattr__
    value = self.__getitem__(item, _ignore_default=True)
            ^^^^^^^^^^^^^^^^^^^^^^^^^^^^^^^^^^^^^^^^^^^^
  File "/home/moses/anaconda3/lib/python3.11/site-packages/box/box.py", line 524, in __getitem__
    raise BoxKeyError(str(err)) from _exception_cause(err)
box.exceptions.BoxKeyError: "'artifacts_root_'"

During handling of the above exception, another exception occurred:

Traceback (most recent call last):
  File "/home/moses/anaconda3/lib/python3.11/site-packages/box/box.py", line 538, in __getattr__
    value = object.__getattribute__(self, item)
            ^^^^^^^^^^^^^^^^^^^^^^^^^^^^^^^^^^^
AttributeError: 'ConfigBox' object has no attribute 'artifacts_root_'

The above exception was the direct cause of the following exception:

Traceback (most recent call last):
  File "/home/moses/Documents/machine_learning/End_to_end_ml_project/main.py", line 10, in <module>
    obj.main()
  File "/home/moses/Documents/machine_learning/End_to_end_ml_project/src/my_project/pipeline/stage_1_data_ingestion.py", line 12, in main
    config = ConfigurationManager()
             ^^^^^^^^^^^^^^^^^^^^^^
  File "/home/moses/Documents/machine_learning/End_to_end_ml_project/src/my_project/config/configuration.py", line 22, in __init__
    create_directories([self.config.artifacts_root_])
                        ^^^^^^^^^^^^^^^^^^^^^^^^^^^
  File "/home/moses/anaconda3/lib/python3.11/site-packages/box/config_box.py", line 30, in __getattr__
    return super().__getattr__(item.lower())
           ^^^^^^^^^^^^^^^^^^^^^^^^^^^^^^^^^
  File "/home/moses/anaconda3/lib/python3.11/site-packages/box/box.py", line 552, in __getattr__
    raise BoxKeyError(str(err)) from _exception_cause(err)
box.exceptions.BoxKeyError: "'ConfigBox' object has no attribute 'artifacts_root_'"
[2025-06-14 10:44:22,840: INFO : main : >> stage Data Ingestion stage has started >>>>]
[2025-06-14 10:44:22,842: INFO : common : YML file: config/config.yaml loaded successfully]
[2025-06-14 10:44:22,843: INFO : common : YML file: params.yaml loaded successfully]
[2025-06-14 10:44:22,845: INFO : common : YML file: schema.yaml loaded successfully]
[2025-06-14 10:44:22,846: ERROR : main : "'ConfigBox' object has no attribute 'artifacts_root_'"]
Traceback (most recent call last):
  File "/home/moses/anaconda3/lib/python3.11/site-packages/box/box.py", line 503, in __getitem__
    return super().__getitem__(item)
           ^^^^^^^^^^^^^^^^^^^^^^^^^
KeyError: 'artifacts_root_'

The above exception was the direct cause of the following exception:

Traceback (most recent call last):
  File "/home/moses/anaconda3/lib/python3.11/site-packages/box/box.py", line 536, in __getattr__
    value = self.__getitem__(item, _ignore_default=True)
            ^^^^^^^^^^^^^^^^^^^^^^^^^^^^^^^^^^^^^^^^^^^^
  File "/home/moses/anaconda3/lib/python3.11/site-packages/box/box.py", line 524, in __getitem__
    raise BoxKeyError(str(err)) from _exception_cause(err)
box.exceptions.BoxKeyError: "'artifacts_root_'"

During handling of the above exception, another exception occurred:

Traceback (most recent call last):
  File "/home/moses/anaconda3/lib/python3.11/site-packages/box/box.py", line 538, in __getattr__
    value = object.__getattribute__(self, item)
            ^^^^^^^^^^^^^^^^^^^^^^^^^^^^^^^^^^^
AttributeError: 'ConfigBox' object has no attribute 'artifacts_root_'

The above exception was the direct cause of the following exception:

Traceback (most recent call last):
  File "/home/moses/anaconda3/lib/python3.11/site-packages/box/config_box.py", line 28, in __getattr__
    return super().__getattr__(item)
           ^^^^^^^^^^^^^^^^^^^^^^^^^
  File "/home/moses/anaconda3/lib/python3.11/site-packages/box/box.py", line 552, in __getattr__
    raise BoxKeyError(str(err)) from _exception_cause(err)
box.exceptions.BoxKeyError: "'ConfigBox' object has no attribute 'artifacts_root_'"

During handling of the above exception, another exception occurred:

Traceback (most recent call last):
  File "/home/moses/anaconda3/lib/python3.11/site-packages/box/box.py", line 503, in __getitem__
    return super().__getitem__(item)
           ^^^^^^^^^^^^^^^^^^^^^^^^^
KeyError: 'artifacts_root_'

The above exception was the direct cause of the following exception:

Traceback (most recent call last):
  File "/home/moses/anaconda3/lib/python3.11/site-packages/box/box.py", line 536, in __getattr__
    value = self.__getitem__(item, _ignore_default=True)
            ^^^^^^^^^^^^^^^^^^^^^^^^^^^^^^^^^^^^^^^^^^^^
  File "/home/moses/anaconda3/lib/python3.11/site-packages/box/box.py", line 524, in __getitem__
    raise BoxKeyError(str(err)) from _exception_cause(err)
box.exceptions.BoxKeyError: "'artifacts_root_'"

During handling of the above exception, another exception occurred:

Traceback (most recent call last):
  File "/home/moses/anaconda3/lib/python3.11/site-packages/box/box.py", line 538, in __getattr__
    value = object.__getattribute__(self, item)
            ^^^^^^^^^^^^^^^^^^^^^^^^^^^^^^^^^^^
AttributeError: 'ConfigBox' object has no attribute 'artifacts_root_'

The above exception was the direct cause of the following exception:

Traceback (most recent call last):
  File "/home/moses/Documents/machine_learning/End_to_end_ml_project/main.py", line 10, in <module>
    obj.main()
  File "/home/moses/Documents/machine_learning/End_to_end_ml_project/src/my_project/pipeline/stage_1_data_ingestion.py", line 12, in main
    config = ConfigurationManager()
             ^^^^^^^^^^^^^^^^^^^^^^
  File "/home/moses/Documents/machine_learning/End_to_end_ml_project/src/my_project/config/configuration.py", line 22, in __init__
    create_directories([self.config.artifacts_root_])
                        ^^^^^^^^^^^^^^^^^^^^^^^^^^^
  File "/home/moses/anaconda3/lib/python3.11/site-packages/box/config_box.py", line 30, in __getattr__
    return super().__getattr__(item.lower())
           ^^^^^^^^^^^^^^^^^^^^^^^^^^^^^^^^^
  File "/home/moses/anaconda3/lib/python3.11/site-packages/box/box.py", line 552, in __getattr__
    raise BoxKeyError(str(err)) from _exception_cause(err)
box.exceptions.BoxKeyError: "'ConfigBox' object has no attribute 'artifacts_root_'"
[2025-06-14 10:49:08,803: INFO : main : >> stage Data Ingestion stage has started >>>>]
[2025-06-14 10:49:08,805: INFO : common : YML file: config/config.yaml loaded successfully]
[2025-06-14 10:49:08,806: INFO : common : YML file: params.yaml loaded successfully]
[2025-06-14 10:49:08,811: INFO : common : YML file: schema.yaml loaded successfully]
[2025-06-14 10:49:08,814: INFO : common : Created directory at: artifacts]
[2025-06-14 10:49:08,817: ERROR : main : Argument path_to_directories of type <class 'str'> to <function create_directories at 0x7f5bb8e82fc0> does not match annotation type <class 'list'>]
Traceback (most recent call last):
  File "/home/moses/Documents/machine_learning/End_to_end_ml_project/main.py", line 10, in <module>
    obj.main()
  File "/home/moses/Documents/machine_learning/End_to_end_ml_project/src/my_project/pipeline/stage_1_data_ingestion.py", line 13, in main
    data_ingestion_config = config.get_data_ingestion_config()
                            ^^^^^^^^^^^^^^^^^^^^^^^^^^^^^^^^^^
  File "/home/moses/Documents/machine_learning/End_to_end_ml_project/src/my_project/config/configuration.py", line 27, in get_data_ingestion_config
    create_directories(config.root_dir)
  File "/home/moses/anaconda3/lib/python3.11/site-packages/ensure/main.py", line 803, in __call__
    raise EnsureError(msg.format(
ensure.main.EnsureError: Argument path_to_directories of type <class 'str'> to <function create_directories at 0x7f5bb8e82fc0> does not match annotation type <class 'list'>
[2025-06-14 10:53:08,464: INFO : common : Created directory at: artifacts]
[2025-06-14 10:53:08,484: INFO : main : >> stage Data Ingestion stage has started >>>>]
[2025-06-14 10:53:08,503: INFO : common : YML file: config/config.yaml loaded successfully]
[2025-06-14 10:53:08,505: INFO : common : YML file: params.yaml loaded successfully]
[2025-06-14 10:53:08,511: INFO : common : YML file: schema.yaml loaded successfully]
[2025-06-14 10:53:08,512: INFO : common : Created directory at: artifacts]
[2025-06-14 10:53:08,512: ERROR : main : Argument path_to_directories of type <class 'str'> to <function create_directories at 0x7fcbd253efc0> does not match annotation type <class 'list'>]
Traceback (most recent call last):
  File "/home/moses/Documents/machine_learning/End_to_end_ml_project/main.py", line 10, in <module>
    obj.main()
  File "/home/moses/Documents/machine_learning/End_to_end_ml_project/src/my_project/pipeline/stage_1_data_ingestion.py", line 13, in main
    data_ingestion_config = config.get_data_ingestion_config()
                            ^^^^^^^^^^^^^^^^^^^^^^^^^^^^^^^^^^
  File "/home/moses/Documents/machine_learning/End_to_end_ml_project/src/my_project/config/configuration.py", line 28, in get_data_ingestion_config
    create_directories(config.root_dir)
  File "/home/moses/anaconda3/lib/python3.11/site-packages/ensure/main.py", line 803, in __call__
    raise EnsureError(msg.format(
ensure.main.EnsureError: Argument path_to_directories of type <class 'str'> to <function create_directories at 0x7fcbd253efc0> does not match annotation type <class 'list'>
[2025-06-14 10:55:55,540: INFO : common : Created directory at: artifacts]
[2025-06-14 10:55:55,581: INFO : main : >> stage Data Ingestion stage has started >>>>]
[2025-06-14 10:55:55,583: INFO : common : YML file: config/config.yaml loaded successfully]
[2025-06-14 10:55:55,586: INFO : common : YML file: params.yaml loaded successfully]
[2025-06-14 10:55:55,590: INFO : common : YML file: schema.yaml loaded successfully]
[2025-06-14 10:55:55,596: INFO : common : Created directory at: artifacts]
[2025-06-14 10:55:55,596: ERROR : main : Argument path_to_directories of type <class 'str'> to <function create_directories at 0x7f93b8a9efc0> does not match annotation type <class 'list'>]
Traceback (most recent call last):
  File "/home/moses/Documents/machine_learning/End_to_end_ml_project/main.py", line 10, in <module>
    obj.main()
  File "/home/moses/Documents/machine_learning/End_to_end_ml_project/src/my_project/pipeline/stage_1_data_ingestion.py", line 13, in main
    data_ingestion_config = config.get_data_ingestion_config()
                            ^^^^^^^^^^^^^^^^^^^^^^^^^^^^^^^^^^
  File "/home/moses/Documents/machine_learning/End_to_end_ml_project/src/my_project/config/configuration.py", line 29, in get_data_ingestion_config
    create_directories(config.root_dir)
  File "/home/moses/anaconda3/lib/python3.11/site-packages/ensure/main.py", line 803, in __call__
    raise EnsureError(msg.format(
ensure.main.EnsureError: Argument path_to_directories of type <class 'str'> to <function create_directories at 0x7f93b8a9efc0> does not match annotation type <class 'list'>
[2025-06-14 10:57:55,555: INFO : common : Created directory at: artifacts]
[2025-06-14 10:57:55,574: INFO : main : >> stage Data Ingestion stage has started >>>>]
[2025-06-14 10:57:55,576: INFO : common : YML file: config/config.yaml loaded successfully]
[2025-06-14 10:57:55,577: INFO : common : YML file: params.yaml loaded successfully]
[2025-06-14 10:57:55,579: INFO : common : YML file: schema.yaml loaded successfully]
[2025-06-14 10:57:55,580: INFO : common : Created directory at: artifacts]
[2025-06-14 10:57:55,581: INFO : common : Created directory at: artifacts/data_ingestion]
[2025-06-14 10:57:55,581: ERROR : main : name 'DataIngestionConfig' is not defined]
Traceback (most recent call last):
  File "/home/moses/Documents/machine_learning/End_to_end_ml_project/main.py", line 10, in <module>
    obj.main()
  File "/home/moses/Documents/machine_learning/End_to_end_ml_project/src/my_project/pipeline/stage_1_data_ingestion.py", line 13, in main
    data_ingestion_config = config.get_data_ingestion_config()
                            ^^^^^^^^^^^^^^^^^^^^^^^^^^^^^^^^^^
  File "/home/moses/Documents/machine_learning/End_to_end_ml_project/src/my_project/config/configuration.py", line 31, in get_data_ingestion_config
    data_download = DataIngestionConfig(
                    ^^^^^^^^^^^^^^^^^^^
NameError: name 'DataIngestionConfig' is not defined
[2025-06-14 11:01:29,476: INFO : common : Created directory at: artifacts]
[2025-06-14 11:04:05,895: INFO : common : Created directory at: artifacts]
[2025-06-14 11:06:12,196: INFO : common : Created directory at: artifacts]
[2025-06-14 11:06:38,473: INFO : common : Created directory at: artifacts]
[2025-06-14 11:06:38,504: INFO : main : >> stage Data Ingestion stage has started >>>>]
[2025-06-14 11:06:38,507: INFO : common : YML file: config/config.yaml loaded successfully]
[2025-06-14 11:06:38,508: INFO : common : YML file: params.yaml loaded successfully]
[2025-06-14 11:06:38,511: INFO : common : YML file: schema.yaml loaded successfully]
[2025-06-14 11:06:38,512: INFO : common : Created directory at: artifacts]
[2025-06-14 11:06:38,513: INFO : common : Created directory at: artifacts/data_ingestion]
[2025-06-14 11:06:38,513: ERROR : main : name 'config_root_dir' is not defined]
Traceback (most recent call last):
  File "/home/moses/Documents/machine_learning/End_to_end_ml_project/main.py", line 10, in <module>
    obj.main()
  File "/home/moses/Documents/machine_learning/End_to_end_ml_project/src/my_project/pipeline/stage_1_data_ingestion.py", line 13, in main
    data_ingestion_config = config.get_data_ingestion_config()
                            ^^^^^^^^^^^^^^^^^^^^^^^^^^^^^^^^^^
  File "/home/moses/Documents/machine_learning/End_to_end_ml_project/src/my_project/config/configuration.py", line 32, in get_data_ingestion_config
    root_dir=config_root_dir,
             ^^^^^^^^^^^^^^^
NameError: name 'config_root_dir' is not defined
[2025-06-14 11:07:53,493: INFO : common : Created directory at: artifacts]
[2025-06-14 11:07:53,514: INFO : main : >> stage Data Ingestion stage has started >>>>]
[2025-06-14 11:07:53,516: INFO : common : YML file: config/config.yaml loaded successfully]
[2025-06-14 11:07:53,516: INFO : common : YML file: params.yaml loaded successfully]
[2025-06-14 11:07:53,519: INFO : common : YML file: schema.yaml loaded successfully]
[2025-06-14 11:07:53,519: INFO : common : Created directory at: artifacts]
[2025-06-14 11:07:53,520: INFO : common : Created directory at: artifacts/data_ingestion]
[2025-06-14 11:07:53,520: ERROR : main : "'ConfigBox' object has no attribute 'source_url'"]
Traceback (most recent call last):
  File "/home/moses/anaconda3/lib/python3.11/site-packages/box/box.py", line 503, in __getitem__
    return super().__getitem__(item)
           ^^^^^^^^^^^^^^^^^^^^^^^^^
KeyError: 'source_url'

The above exception was the direct cause of the following exception:

Traceback (most recent call last):
  File "/home/moses/anaconda3/lib/python3.11/site-packages/box/box.py", line 536, in __getattr__
    value = self.__getitem__(item, _ignore_default=True)
            ^^^^^^^^^^^^^^^^^^^^^^^^^^^^^^^^^^^^^^^^^^^^
  File "/home/moses/anaconda3/lib/python3.11/site-packages/box/box.py", line 524, in __getitem__
    raise BoxKeyError(str(err)) from _exception_cause(err)
box.exceptions.BoxKeyError: "'source_url'"

During handling of the above exception, another exception occurred:

Traceback (most recent call last):
  File "/home/moses/anaconda3/lib/python3.11/site-packages/box/box.py", line 538, in __getattr__
    value = object.__getattribute__(self, item)
            ^^^^^^^^^^^^^^^^^^^^^^^^^^^^^^^^^^^
AttributeError: 'ConfigBox' object has no attribute 'source_url'

The above exception was the direct cause of the following exception:

Traceback (most recent call last):
  File "/home/moses/anaconda3/lib/python3.11/site-packages/box/config_box.py", line 28, in __getattr__
    return super().__getattr__(item)
           ^^^^^^^^^^^^^^^^^^^^^^^^^
  File "/home/moses/anaconda3/lib/python3.11/site-packages/box/box.py", line 552, in __getattr__
    raise BoxKeyError(str(err)) from _exception_cause(err)
box.exceptions.BoxKeyError: "'ConfigBox' object has no attribute 'source_url'"

During handling of the above exception, another exception occurred:

Traceback (most recent call last):
  File "/home/moses/anaconda3/lib/python3.11/site-packages/box/box.py", line 503, in __getitem__
    return super().__getitem__(item)
           ^^^^^^^^^^^^^^^^^^^^^^^^^
KeyError: 'source_url'

The above exception was the direct cause of the following exception:

Traceback (most recent call last):
  File "/home/moses/anaconda3/lib/python3.11/site-packages/box/box.py", line 536, in __getattr__
    value = self.__getitem__(item, _ignore_default=True)
            ^^^^^^^^^^^^^^^^^^^^^^^^^^^^^^^^^^^^^^^^^^^^
  File "/home/moses/anaconda3/lib/python3.11/site-packages/box/box.py", line 524, in __getitem__
    raise BoxKeyError(str(err)) from _exception_cause(err)
box.exceptions.BoxKeyError: "'source_url'"

During handling of the above exception, another exception occurred:

Traceback (most recent call last):
  File "/home/moses/anaconda3/lib/python3.11/site-packages/box/box.py", line 538, in __getattr__
    value = object.__getattribute__(self, item)
            ^^^^^^^^^^^^^^^^^^^^^^^^^^^^^^^^^^^
AttributeError: 'ConfigBox' object has no attribute 'source_url'

The above exception was the direct cause of the following exception:

Traceback (most recent call last):
  File "/home/moses/Documents/machine_learning/End_to_end_ml_project/main.py", line 10, in <module>
    obj.main()
  File "/home/moses/Documents/machine_learning/End_to_end_ml_project/src/my_project/pipeline/stage_1_data_ingestion.py", line 13, in main
    data_ingestion_config = config.get_data_ingestion_config()
                            ^^^^^^^^^^^^^^^^^^^^^^^^^^^^^^^^^^
  File "/home/moses/Documents/machine_learning/End_to_end_ml_project/src/my_project/config/configuration.py", line 33, in get_data_ingestion_config
    source_url=config.source_url,
               ^^^^^^^^^^^^^^^^^
  File "/home/moses/anaconda3/lib/python3.11/site-packages/box/config_box.py", line 30, in __getattr__
    return super().__getattr__(item.lower())
           ^^^^^^^^^^^^^^^^^^^^^^^^^^^^^^^^^
  File "/home/moses/anaconda3/lib/python3.11/site-packages/box/box.py", line 552, in __getattr__
    raise BoxKeyError(str(err)) from _exception_cause(err)
box.exceptions.BoxKeyError: "'ConfigBox' object has no attribute 'source_url'"
[2025-06-14 11:10:50,214: INFO : common : Created directory at: artifacts]
[2025-06-14 11:10:50,234: INFO : main : >> stage Data Ingestion stage has started >>>>]
[2025-06-14 11:10:50,236: INFO : common : YML file: config/config.yaml loaded successfully]
[2025-06-14 11:10:50,237: INFO : common : YML file: params.yaml loaded successfully]
[2025-06-14 11:10:50,240: INFO : common : YML file: schema.yaml loaded successfully]
[2025-06-14 11:10:50,240: INFO : common : Created directory at: artifacts]
[2025-06-14 11:10:50,241: INFO : common : Created directory at: artifacts/data_ingestion]
[2025-06-14 11:10:50,241: ERROR : main : "'ConfigBox' object has no attribute 'source_url'"]
Traceback (most recent call last):
  File "/home/moses/anaconda3/lib/python3.11/site-packages/box/box.py", line 503, in __getitem__
    return super().__getitem__(item)
           ^^^^^^^^^^^^^^^^^^^^^^^^^
KeyError: 'source_url'

The above exception was the direct cause of the following exception:

Traceback (most recent call last):
  File "/home/moses/anaconda3/lib/python3.11/site-packages/box/box.py", line 536, in __getattr__
    value = self.__getitem__(item, _ignore_default=True)
            ^^^^^^^^^^^^^^^^^^^^^^^^^^^^^^^^^^^^^^^^^^^^
  File "/home/moses/anaconda3/lib/python3.11/site-packages/box/box.py", line 524, in __getitem__
    raise BoxKeyError(str(err)) from _exception_cause(err)
box.exceptions.BoxKeyError: "'source_url'"

During handling of the above exception, another exception occurred:

Traceback (most recent call last):
  File "/home/moses/anaconda3/lib/python3.11/site-packages/box/box.py", line 538, in __getattr__
    value = object.__getattribute__(self, item)
            ^^^^^^^^^^^^^^^^^^^^^^^^^^^^^^^^^^^
AttributeError: 'ConfigBox' object has no attribute 'source_url'

The above exception was the direct cause of the following exception:

Traceback (most recent call last):
  File "/home/moses/anaconda3/lib/python3.11/site-packages/box/config_box.py", line 28, in __getattr__
    return super().__getattr__(item)
           ^^^^^^^^^^^^^^^^^^^^^^^^^
  File "/home/moses/anaconda3/lib/python3.11/site-packages/box/box.py", line 552, in __getattr__
    raise BoxKeyError(str(err)) from _exception_cause(err)
box.exceptions.BoxKeyError: "'ConfigBox' object has no attribute 'source_url'"

During handling of the above exception, another exception occurred:

Traceback (most recent call last):
  File "/home/moses/anaconda3/lib/python3.11/site-packages/box/box.py", line 503, in __getitem__
    return super().__getitem__(item)
           ^^^^^^^^^^^^^^^^^^^^^^^^^
KeyError: 'source_url'

The above exception was the direct cause of the following exception:

Traceback (most recent call last):
  File "/home/moses/anaconda3/lib/python3.11/site-packages/box/box.py", line 536, in __getattr__
    value = self.__getitem__(item, _ignore_default=True)
            ^^^^^^^^^^^^^^^^^^^^^^^^^^^^^^^^^^^^^^^^^^^^
  File "/home/moses/anaconda3/lib/python3.11/site-packages/box/box.py", line 524, in __getitem__
    raise BoxKeyError(str(err)) from _exception_cause(err)
box.exceptions.BoxKeyError: "'source_url'"

During handling of the above exception, another exception occurred:

Traceback (most recent call last):
  File "/home/moses/anaconda3/lib/python3.11/site-packages/box/box.py", line 538, in __getattr__
    value = object.__getattribute__(self, item)
            ^^^^^^^^^^^^^^^^^^^^^^^^^^^^^^^^^^^
AttributeError: 'ConfigBox' object has no attribute 'source_url'

The above exception was the direct cause of the following exception:

Traceback (most recent call last):
  File "/home/moses/Documents/machine_learning/End_to_end_ml_project/main.py", line 10, in <module>
    obj.main()
  File "/home/moses/Documents/machine_learning/End_to_end_ml_project/src/my_project/pipeline/stage_1_data_ingestion.py", line 13, in main
    data_ingestion_config = config.get_data_ingestion_config()
                            ^^^^^^^^^^^^^^^^^^^^^^^^^^^^^^^^^^
  File "/home/moses/Documents/machine_learning/End_to_end_ml_project/src/my_project/config/configuration.py", line 33, in get_data_ingestion_config
    source_url=config.source_url,
               ^^^^^^^^^^^^^^^^^
  File "/home/moses/anaconda3/lib/python3.11/site-packages/box/config_box.py", line 30, in __getattr__
    return super().__getattr__(item.lower())
           ^^^^^^^^^^^^^^^^^^^^^^^^^^^^^^^^^
  File "/home/moses/anaconda3/lib/python3.11/site-packages/box/box.py", line 552, in __getattr__
    raise BoxKeyError(str(err)) from _exception_cause(err)
box.exceptions.BoxKeyError: "'ConfigBox' object has no attribute 'source_url'"
[2025-06-14 11:11:36,011: INFO : common : Created directory at: artifacts]
[2025-06-14 11:11:36,030: INFO : main : >> stage Data Ingestion stage has started >>>>]
[2025-06-14 11:11:36,032: INFO : common : YML file: config/config.yaml loaded successfully]
[2025-06-14 11:11:36,032: INFO : common : YML file: params.yaml loaded successfully]
[2025-06-14 11:11:36,035: INFO : common : YML file: schema.yaml loaded successfully]
[2025-06-14 11:11:36,035: INFO : common : Created directory at: artifacts]
[2025-06-14 11:11:36,035: INFO : common : Created directory at: artifacts/data_ingestion]
[2025-06-14 11:11:36,036: ERROR : main : "'ConfigBox' object has no attribute 'source_url'"]
Traceback (most recent call last):
  File "/home/moses/anaconda3/lib/python3.11/site-packages/box/box.py", line 503, in __getitem__
    return super().__getitem__(item)
           ^^^^^^^^^^^^^^^^^^^^^^^^^
KeyError: 'source_url'

The above exception was the direct cause of the following exception:

Traceback (most recent call last):
  File "/home/moses/anaconda3/lib/python3.11/site-packages/box/box.py", line 536, in __getattr__
    value = self.__getitem__(item, _ignore_default=True)
            ^^^^^^^^^^^^^^^^^^^^^^^^^^^^^^^^^^^^^^^^^^^^
  File "/home/moses/anaconda3/lib/python3.11/site-packages/box/box.py", line 524, in __getitem__
    raise BoxKeyError(str(err)) from _exception_cause(err)
box.exceptions.BoxKeyError: "'source_url'"

During handling of the above exception, another exception occurred:

Traceback (most recent call last):
  File "/home/moses/anaconda3/lib/python3.11/site-packages/box/box.py", line 538, in __getattr__
    value = object.__getattribute__(self, item)
            ^^^^^^^^^^^^^^^^^^^^^^^^^^^^^^^^^^^
AttributeError: 'ConfigBox' object has no attribute 'source_url'

The above exception was the direct cause of the following exception:

Traceback (most recent call last):
  File "/home/moses/anaconda3/lib/python3.11/site-packages/box/config_box.py", line 28, in __getattr__
    return super().__getattr__(item)
           ^^^^^^^^^^^^^^^^^^^^^^^^^
  File "/home/moses/anaconda3/lib/python3.11/site-packages/box/box.py", line 552, in __getattr__
    raise BoxKeyError(str(err)) from _exception_cause(err)
box.exceptions.BoxKeyError: "'ConfigBox' object has no attribute 'source_url'"

During handling of the above exception, another exception occurred:

Traceback (most recent call last):
  File "/home/moses/anaconda3/lib/python3.11/site-packages/box/box.py", line 503, in __getitem__
    return super().__getitem__(item)
           ^^^^^^^^^^^^^^^^^^^^^^^^^
KeyError: 'source_url'

The above exception was the direct cause of the following exception:

Traceback (most recent call last):
  File "/home/moses/anaconda3/lib/python3.11/site-packages/box/box.py", line 536, in __getattr__
    value = self.__getitem__(item, _ignore_default=True)
            ^^^^^^^^^^^^^^^^^^^^^^^^^^^^^^^^^^^^^^^^^^^^
  File "/home/moses/anaconda3/lib/python3.11/site-packages/box/box.py", line 524, in __getitem__
    raise BoxKeyError(str(err)) from _exception_cause(err)
box.exceptions.BoxKeyError: "'source_url'"

During handling of the above exception, another exception occurred:

Traceback (most recent call last):
  File "/home/moses/anaconda3/lib/python3.11/site-packages/box/box.py", line 538, in __getattr__
    value = object.__getattribute__(self, item)
            ^^^^^^^^^^^^^^^^^^^^^^^^^^^^^^^^^^^
AttributeError: 'ConfigBox' object has no attribute 'source_url'

The above exception was the direct cause of the following exception:

Traceback (most recent call last):
  File "/home/moses/Documents/machine_learning/End_to_end_ml_project/main.py", line 10, in <module>
    obj.main()
  File "/home/moses/Documents/machine_learning/End_to_end_ml_project/src/my_project/pipeline/stage_1_data_ingestion.py", line 13, in main
    data_ingestion_config = config.get_data_ingestion_config()
                            ^^^^^^^^^^^^^^^^^^^^^^^^^^^^^^^^^^
  File "/home/moses/Documents/machine_learning/End_to_end_ml_project/src/my_project/config/configuration.py", line 33, in get_data_ingestion_config
    source_URL=config.source_url,
               ^^^^^^^^^^^^^^^^^
  File "/home/moses/anaconda3/lib/python3.11/site-packages/box/config_box.py", line 30, in __getattr__
    return super().__getattr__(item.lower())
           ^^^^^^^^^^^^^^^^^^^^^^^^^^^^^^^^^
  File "/home/moses/anaconda3/lib/python3.11/site-packages/box/box.py", line 552, in __getattr__
    raise BoxKeyError(str(err)) from _exception_cause(err)
box.exceptions.BoxKeyError: "'ConfigBox' object has no attribute 'source_url'"
[2025-06-14 11:12:58,159: INFO : common : Created directory at: artifacts]
[2025-06-14 11:12:58,179: INFO : main : >> stage Data Ingestion stage has started >>>>]
[2025-06-14 11:12:58,181: INFO : common : YML file: config/config.yaml loaded successfully]
[2025-06-14 11:12:58,182: INFO : common : YML file: params.yaml loaded successfully]
[2025-06-14 11:12:58,184: INFO : common : YML file: schema.yaml loaded successfully]
[2025-06-14 11:12:58,185: INFO : common : Created directory at: artifacts]
[2025-06-14 11:12:58,185: INFO : common : Created directory at: artifacts/data_ingestion]
[2025-06-14 11:12:58,185: ERROR : main : "'ConfigBox' object has no attribute 'unzip_dir'"]
Traceback (most recent call last):
  File "/home/moses/anaconda3/lib/python3.11/site-packages/box/box.py", line 503, in __getitem__
    return super().__getitem__(item)
           ^^^^^^^^^^^^^^^^^^^^^^^^^
KeyError: 'unzip_dir'

The above exception was the direct cause of the following exception:

Traceback (most recent call last):
  File "/home/moses/anaconda3/lib/python3.11/site-packages/box/box.py", line 536, in __getattr__
    value = self.__getitem__(item, _ignore_default=True)
            ^^^^^^^^^^^^^^^^^^^^^^^^^^^^^^^^^^^^^^^^^^^^
  File "/home/moses/anaconda3/lib/python3.11/site-packages/box/box.py", line 524, in __getitem__
    raise BoxKeyError(str(err)) from _exception_cause(err)
box.exceptions.BoxKeyError: "'unzip_dir'"

During handling of the above exception, another exception occurred:

Traceback (most recent call last):
  File "/home/moses/anaconda3/lib/python3.11/site-packages/box/box.py", line 538, in __getattr__
    value = object.__getattribute__(self, item)
            ^^^^^^^^^^^^^^^^^^^^^^^^^^^^^^^^^^^
AttributeError: 'ConfigBox' object has no attribute 'unzip_dir'

The above exception was the direct cause of the following exception:

Traceback (most recent call last):
  File "/home/moses/anaconda3/lib/python3.11/site-packages/box/config_box.py", line 28, in __getattr__
    return super().__getattr__(item)
           ^^^^^^^^^^^^^^^^^^^^^^^^^
  File "/home/moses/anaconda3/lib/python3.11/site-packages/box/box.py", line 552, in __getattr__
    raise BoxKeyError(str(err)) from _exception_cause(err)
box.exceptions.BoxKeyError: "'ConfigBox' object has no attribute 'unzip_dir'"

During handling of the above exception, another exception occurred:

Traceback (most recent call last):
  File "/home/moses/anaconda3/lib/python3.11/site-packages/box/box.py", line 503, in __getitem__
    return super().__getitem__(item)
           ^^^^^^^^^^^^^^^^^^^^^^^^^
KeyError: 'unzip_dir'

The above exception was the direct cause of the following exception:

Traceback (most recent call last):
  File "/home/moses/anaconda3/lib/python3.11/site-packages/box/box.py", line 536, in __getattr__
    value = self.__getitem__(item, _ignore_default=True)
            ^^^^^^^^^^^^^^^^^^^^^^^^^^^^^^^^^^^^^^^^^^^^
  File "/home/moses/anaconda3/lib/python3.11/site-packages/box/box.py", line 524, in __getitem__
    raise BoxKeyError(str(err)) from _exception_cause(err)
box.exceptions.BoxKeyError: "'unzip_dir'"

During handling of the above exception, another exception occurred:

Traceback (most recent call last):
  File "/home/moses/anaconda3/lib/python3.11/site-packages/box/box.py", line 538, in __getattr__
    value = object.__getattribute__(self, item)
            ^^^^^^^^^^^^^^^^^^^^^^^^^^^^^^^^^^^
AttributeError: 'ConfigBox' object has no attribute 'unzip_dir'

The above exception was the direct cause of the following exception:

Traceback (most recent call last):
  File "/home/moses/Documents/machine_learning/End_to_end_ml_project/main.py", line 10, in <module>
    obj.main()
  File "/home/moses/Documents/machine_learning/End_to_end_ml_project/src/my_project/pipeline/stage_1_data_ingestion.py", line 13, in main
    data_ingestion_config = config.get_data_ingestion_config()
                            ^^^^^^^^^^^^^^^^^^^^^^^^^^^^^^^^^^
  File "/home/moses/Documents/machine_learning/End_to_end_ml_project/src/my_project/config/configuration.py", line 35, in get_data_ingestion_config
    unzip_dir=config.unzip_dir
              ^^^^^^^^^^^^^^^^
  File "/home/moses/anaconda3/lib/python3.11/site-packages/box/config_box.py", line 30, in __getattr__
    return super().__getattr__(item.lower())
           ^^^^^^^^^^^^^^^^^^^^^^^^^^^^^^^^^
  File "/home/moses/anaconda3/lib/python3.11/site-packages/box/box.py", line 552, in __getattr__
    raise BoxKeyError(str(err)) from _exception_cause(err)
box.exceptions.BoxKeyError: "'ConfigBox' object has no attribute 'unzip_dir'"
[2025-06-14 11:14:14,997: INFO : common : Created directory at: artifacts]
[2025-06-14 11:14:15,017: INFO : main : >> stage Data Ingestion stage has started >>>>]
[2025-06-14 11:14:15,019: INFO : common : YML file: config/config.yaml loaded successfully]
[2025-06-14 11:14:15,019: INFO : common : YML file: params.yaml loaded successfully]
[2025-06-14 11:14:15,022: INFO : common : YML file: schema.yaml loaded successfully]
[2025-06-14 11:14:15,022: INFO : common : Created directory at: artifacts]
[2025-06-14 11:14:15,023: INFO : common : Created directory at: artifacts/data_ingestion]
[2025-06-14 11:14:15,023: ERROR : main : "'ConfigBox' object has no attribute 'unzip_dir'"]
Traceback (most recent call last):
  File "/home/moses/anaconda3/lib/python3.11/site-packages/box/box.py", line 503, in __getitem__
    return super().__getitem__(item)
           ^^^^^^^^^^^^^^^^^^^^^^^^^
KeyError: 'unzip_dir'

The above exception was the direct cause of the following exception:

Traceback (most recent call last):
  File "/home/moses/anaconda3/lib/python3.11/site-packages/box/box.py", line 536, in __getattr__
    value = self.__getitem__(item, _ignore_default=True)
            ^^^^^^^^^^^^^^^^^^^^^^^^^^^^^^^^^^^^^^^^^^^^
  File "/home/moses/anaconda3/lib/python3.11/site-packages/box/box.py", line 524, in __getitem__
    raise BoxKeyError(str(err)) from _exception_cause(err)
box.exceptions.BoxKeyError: "'unzip_dir'"

During handling of the above exception, another exception occurred:

Traceback (most recent call last):
  File "/home/moses/anaconda3/lib/python3.11/site-packages/box/box.py", line 538, in __getattr__
    value = object.__getattribute__(self, item)
            ^^^^^^^^^^^^^^^^^^^^^^^^^^^^^^^^^^^
AttributeError: 'ConfigBox' object has no attribute 'unzip_dir'

The above exception was the direct cause of the following exception:

Traceback (most recent call last):
  File "/home/moses/anaconda3/lib/python3.11/site-packages/box/config_box.py", line 28, in __getattr__
    return super().__getattr__(item)
           ^^^^^^^^^^^^^^^^^^^^^^^^^
  File "/home/moses/anaconda3/lib/python3.11/site-packages/box/box.py", line 552, in __getattr__
    raise BoxKeyError(str(err)) from _exception_cause(err)
box.exceptions.BoxKeyError: "'ConfigBox' object has no attribute 'unzip_dir'"

During handling of the above exception, another exception occurred:

Traceback (most recent call last):
  File "/home/moses/anaconda3/lib/python3.11/site-packages/box/box.py", line 503, in __getitem__
    return super().__getitem__(item)
           ^^^^^^^^^^^^^^^^^^^^^^^^^
KeyError: 'unzip_dir'

The above exception was the direct cause of the following exception:

Traceback (most recent call last):
  File "/home/moses/anaconda3/lib/python3.11/site-packages/box/box.py", line 536, in __getattr__
    value = self.__getitem__(item, _ignore_default=True)
            ^^^^^^^^^^^^^^^^^^^^^^^^^^^^^^^^^^^^^^^^^^^^
  File "/home/moses/anaconda3/lib/python3.11/site-packages/box/box.py", line 524, in __getitem__
    raise BoxKeyError(str(err)) from _exception_cause(err)
box.exceptions.BoxKeyError: "'unzip_dir'"

During handling of the above exception, another exception occurred:

Traceback (most recent call last):
  File "/home/moses/anaconda3/lib/python3.11/site-packages/box/box.py", line 538, in __getattr__
    value = object.__getattribute__(self, item)
            ^^^^^^^^^^^^^^^^^^^^^^^^^^^^^^^^^^^
AttributeError: 'ConfigBox' object has no attribute 'unzip_dir'

The above exception was the direct cause of the following exception:

Traceback (most recent call last):
  File "/home/moses/Documents/machine_learning/End_to_end_ml_project/main.py", line 10, in <module>
    obj.main()
  File "/home/moses/Documents/machine_learning/End_to_end_ml_project/src/my_project/pipeline/stage_1_data_ingestion.py", line 13, in main
    data_ingestion_config = config.get_data_ingestion_config()
                            ^^^^^^^^^^^^^^^^^^^^^^^^^^^^^^^^^^
  File "/home/moses/Documents/machine_learning/End_to_end_ml_project/src/my_project/config/configuration.py", line 35, in get_data_ingestion_config
    unzip_dir=config.unzip_dir
              ^^^^^^^^^^^^^^^^
  File "/home/moses/anaconda3/lib/python3.11/site-packages/box/config_box.py", line 30, in __getattr__
    return super().__getattr__(item.lower())
           ^^^^^^^^^^^^^^^^^^^^^^^^^^^^^^^^^
  File "/home/moses/anaconda3/lib/python3.11/site-packages/box/box.py", line 552, in __getattr__
    raise BoxKeyError(str(err)) from _exception_cause(err)
box.exceptions.BoxKeyError: "'ConfigBox' object has no attribute 'unzip_dir'"
[2025-06-14 11:14:44,778: INFO : common : Created directory at: artifacts]
[2025-06-14 11:14:44,797: INFO : main : >> stage Data Ingestion stage has started >>>>]
[2025-06-14 11:14:44,799: INFO : common : YML file: config/config.yaml loaded successfully]
[2025-06-14 11:14:44,800: INFO : common : YML file: params.yaml loaded successfully]
[2025-06-14 11:14:44,803: INFO : common : YML file: schema.yaml loaded successfully]
[2025-06-14 11:14:44,803: INFO : common : Created directory at: artifacts]
[2025-06-14 11:14:44,804: INFO : common : Created directory at: artifacts/data_ingestion]
[2025-06-14 11:14:44,804: ERROR : main : DataIngestionConfig.__init__() got an unexpected keyword argument 'source_url']
Traceback (most recent call last):
  File "/home/moses/Documents/machine_learning/End_to_end_ml_project/main.py", line 10, in <module>
    obj.main()
  File "/home/moses/Documents/machine_learning/End_to_end_ml_project/src/my_project/pipeline/stage_1_data_ingestion.py", line 13, in main
    data_ingestion_config = config.get_data_ingestion_config()
                            ^^^^^^^^^^^^^^^^^^^^^^^^^^^^^^^^^^
  File "/home/moses/Documents/machine_learning/End_to_end_ml_project/src/my_project/config/configuration.py", line 31, in get_data_ingestion_config
    data_download = DataIngestionConfig(
                    ^^^^^^^^^^^^^^^^^^^^
TypeError: DataIngestionConfig.__init__() got an unexpected keyword argument 'source_url'
[2025-06-14 11:18:03,579: INFO : common : Created directory at: artifacts]
[2025-06-14 11:18:03,600: INFO : main : >> stage Data Ingestion stage has started >>>>]
[2025-06-14 11:18:03,602: INFO : common : YML file: config/config.yaml loaded successfully]
[2025-06-14 11:18:03,603: INFO : common : YML file: params.yaml loaded successfully]
[2025-06-14 11:18:03,605: INFO : common : YML file: schema.yaml loaded successfully]
[2025-06-14 11:18:03,606: INFO : common : Created directory at: artifacts]
[2025-06-14 11:18:03,606: INFO : common : Created directory at: artifacts/data_ingestion]
[2025-06-14 11:18:03,607: ERROR : main : module 'os' has no attribute 'path_existas']
Traceback (most recent call last):
  File "/home/moses/Documents/machine_learning/End_to_end_ml_project/main.py", line 10, in <module>
    obj.main()
  File "/home/moses/Documents/machine_learning/End_to_end_ml_project/src/my_project/pipeline/stage_1_data_ingestion.py", line 15, in main
    data_ingestion.download_file()
  File "/home/moses/Documents/machine_learning/End_to_end_ml_project/src/my_project/Components/data_ingestion.py", line 14, in download_file
    if not os.path_existas(self.config.local_data_file):
           ^^^^^^^^^^^^^^^
AttributeError: module 'os' has no attribute 'path_existas'
[2025-06-14 11:18:49,997: INFO : common : Created directory at: artifacts]
[2025-06-14 11:18:50,020: INFO : main : >> stage Data Ingestion stage has started >>>>]
[2025-06-14 11:18:50,022: INFO : common : YML file: config/config.yaml loaded successfully]
[2025-06-14 11:18:50,023: INFO : common : YML file: params.yaml loaded successfully]
[2025-06-14 11:18:50,025: INFO : common : YML file: schema.yaml loaded successfully]
[2025-06-14 11:18:50,026: INFO : common : Created directory at: artifacts]
[2025-06-14 11:18:50,026: INFO : common : Created directory at: artifacts/data_ingestion]
[2025-06-14 11:18:50,026: ERROR : main : module 'os' has no attribute 'path_exists']
Traceback (most recent call last):
  File "/home/moses/Documents/machine_learning/End_to_end_ml_project/main.py", line 10, in <module>
    obj.main()
  File "/home/moses/Documents/machine_learning/End_to_end_ml_project/src/my_project/pipeline/stage_1_data_ingestion.py", line 15, in main
    data_ingestion.download_file()
  File "/home/moses/Documents/machine_learning/End_to_end_ml_project/src/my_project/Components/data_ingestion.py", line 14, in download_file
    if not os.path_exists(self.config.local_data_file):
           ^^^^^^^^^^^^^^
AttributeError: module 'os' has no attribute 'path_exists'
[2025-06-14 11:21:06,604: INFO : common : Created directory at: artifacts]
[2025-06-14 11:21:06,629: INFO : main : >> stage Data Ingestion stage has started >>>>]
[2025-06-14 11:21:06,631: INFO : common : YML file: config/config.yaml loaded successfully]
[2025-06-14 11:21:06,632: INFO : common : YML file: params.yaml loaded successfully]
[2025-06-14 11:21:06,634: INFO : common : YML file: schema.yaml loaded successfully]
[2025-06-14 11:21:06,635: INFO : common : Created directory at: artifacts]
[2025-06-14 11:21:06,635: INFO : common : Created directory at: artifacts/data_ingestion]
[2025-06-14 11:21:06,676: ERROR : main : 'DataIngestionConfig' object has no attribute 'local']
Traceback (most recent call last):
  File "/home/moses/Documents/machine_learning/End_to_end_ml_project/main.py", line 10, in <module>
    obj.main()
  File "/home/moses/Documents/machine_learning/End_to_end_ml_project/src/my_project/pipeline/stage_1_data_ingestion.py", line 15, in main
    data_ingestion.download_file()
  File "/home/moses/Documents/machine_learning/End_to_end_ml_project/src/my_project/Components/data_ingestion.py", line 17, in download_file
    filename = self.config.local-data_file
               ^^^^^^^^^^^^^^^^^
AttributeError: 'DataIngestionConfig' object has no attribute 'local'
[2025-06-14 11:25:53,308: INFO : common : Created directory at: artifacts]
[2025-06-14 11:25:53,332: INFO : main : >> stage Data Ingestion stage has started >>>>]
[2025-06-14 11:25:53,334: INFO : common : YML file: config/config.yaml loaded successfully]
[2025-06-14 11:25:53,334: INFO : common : YML file: params.yaml loaded successfully]
[2025-06-14 11:25:53,337: INFO : common : YML file: schema.yaml loaded successfully]
[2025-06-14 11:25:53,337: INFO : common : Created directory at: artifacts]
[2025-06-14 11:25:53,337: INFO : common : Created directory at: artifacts/data_ingestion]
[2025-06-14 11:25:56,071: INFO : data_ingestion : artifacts/data_ingestion/data.zip download: with the following info: 
Connection: close
Content-Length: 23329
Cache-Control: max-age=300
Content-Security-Policy: default-src 'none'; style-src 'unsafe-inline'; sandbox
Content-Type: application/zip
ETag: "c69888a4ae59bc5a893392785a938ccd4937981c06ba8a9d6a21aa52b4ab5b6e"
Strict-Transport-Security: max-age=31536000
X-Content-Type-Options: nosniff
X-Frame-Options: deny
X-XSS-Protection: 1; mode=block
X-GitHub-Request-Id: 68D7:15A646:DFFE79:11A86F1:684D3212
Accept-Ranges: bytes
Date: Sat, 14 Jun 2025 08:25:55 GMT
Via: 1.1 varnish
X-Served-By: cache-fjr990032-FJR
X-Cache: MISS
X-Cache-Hits: 0
X-Timer: S1749889555.415016,VS0,VE380
Vary: Authorization,Accept-Encoding
Access-Control-Allow-Origin: *
Cross-Origin-Resource-Policy: cross-origin
X-Fastly-Request-ID: 49d66bfb004d8b97ad636cdcf0e02b855da10266
Expires: Sat, 14 Jun 2025 08:30:55 GMT
Source-Age: 0

]
[2025-06-14 11:25:56,104: INFO : main : >>>> stage Data Ingestion stage completed >>>>>]
[2025-06-19 11:43:17,245: INFO : common : Created directory at: artifacts]
[2025-06-19 11:57:56,780: INFO : common : Created directory at: artifacts]
[2025-06-19 11:59:28,371: INFO : common : Created directory at: artifacts]
[2025-06-19 11:59:28,420: INFO : main : >> stage Data Ingestion stage has started >>>>]
[2025-06-19 11:59:28,422: INFO : common : YML file: config/config.yaml loaded successfully]
[2025-06-19 11:59:28,424: INFO : common : YML file: params.yaml loaded successfully]
[2025-06-19 11:59:28,426: INFO : common : YML file: schema.yaml loaded successfully]
[2025-06-19 11:59:28,427: INFO : common : Created directory at: artifacts]
[2025-06-19 11:59:28,427: ERROR : main : 'ConfigurationManager' object has no attribute 'get_data_ingestion_config']
Traceback (most recent call last):
  File "/home/moses/Documents/machine_learning/End_to_end_ml_project/main.py", line 11, in <module>
    obj.main()
  File "/home/moses/Documents/machine_learning/End_to_end_ml_project/src/my_project/pipeline/ingestion_stage.py", line 13, in main
    data_ingestion_config = config.get_data_ingestion_config()
                            ^^^^^^^^^^^^^^^^^^^^^^^^^^^^^^^^
AttributeError: 'ConfigurationManager' object has no attribute 'get_data_ingestion_config'
[2025-06-19 23:35:13,251: INFO : common : Created directory at: artifacts]
[2025-06-19 23:35:13,743: INFO : main : >> stage Data Ingestion stage has started >>>>]
[2025-06-19 23:35:13,759: INFO : common : YML file: config/config.yaml loaded successfully]
[2025-06-19 23:35:13,802: INFO : common : YML file: params.yaml loaded successfully]
[2025-06-19 23:35:13,805: INFO : common : YML file: schema.yaml loaded successfully]
[2025-06-19 23:35:13,808: INFO : common : Created directory at: artifacts]
[2025-06-19 23:35:13,810: ERROR : main : 'ConfigurationManager' object has no attribute 'get_data_ingestion_config']
Traceback (most recent call last):
  File "/home/moses/Documents/machine_learning/End_to_end_ml_project/main.py", line 11, in <module>
    obj.main()
  File "/home/moses/Documents/machine_learning/End_to_end_ml_project/src/my_project/pipeline/ingestion_stage.py", line 13, in main
    data_ingestion_config = config.get_data_ingestion_config()
                            ^^^^^^^^^^^^^^^^^^^^^^^^^^^^^^^^
AttributeError: 'ConfigurationManager' object has no attribute 'get_data_ingestion_config'
[2025-06-19 23:44:21,512: INFO : common : Created directory at: artifacts]
[2025-06-19 23:44:21,531: INFO : main : >> stage Data Ingestion stage has started >>>>]
[2025-06-19 23:44:21,534: INFO : common : YML file: config/config.yaml loaded successfully]
[2025-06-19 23:44:21,535: INFO : common : YML file: params.yaml loaded successfully]
[2025-06-19 23:44:21,537: INFO : common : YML file: schema.yaml loaded successfully]
[2025-06-19 23:44:21,537: INFO : common : Created directory at: artifacts]
[2025-06-19 23:44:21,537: ERROR : main : 'ConfigurationManager' object has no attribute 'get_data_ingestion_config']
Traceback (most recent call last):
  File "/home/moses/Documents/machine_learning/End_to_end_ml_project/main.py", line 11, in <module>
    obj.main()
  File "/home/moses/Documents/machine_learning/End_to_end_ml_project/src/my_project/pipeline/ingestion_stage.py", line 13, in main
    data_ingestion_config = config.get_data_ingestion_config()
                            ^^^^^^^^^^^^^^^^^^^^^^^^^^^^^^^^
AttributeError: 'ConfigurationManager' object has no attribute 'get_data_ingestion_config'
[2025-06-19 23:57:44,065: INFO : common : Created directory at: artifacts]
[2025-06-19 23:57:44,087: INFO : main : >> stage Data Ingestion stage has started >>>>]
[2025-06-19 23:57:44,089: INFO : common : YML file: config/config.yaml loaded successfully]
[2025-06-19 23:57:44,090: INFO : common : YML file: params.yaml loaded successfully]
[2025-06-19 23:57:44,092: INFO : common : YML file: schema.yaml loaded successfully]
[2025-06-19 23:57:44,093: INFO : common : Created directory at: artifacts]
[2025-06-19 23:57:44,093: ERROR : main : 'ConfigurationManager' object has no attribute 'get_data_ingestion_config']
Traceback (most recent call last):
  File "/home/moses/Documents/machine_learning/End_to_end_ml_project/main.py", line 11, in <module>
    obj.main()
  File "/home/moses/Documents/machine_learning/End_to_end_ml_project/src/my_project/pipeline/ingestion_stage.py", line 13, in main
    data_ingestion_config = config.get_data_ingestion_config()
                            ^^^^^^^^^^^^^^^^^^^^^^^^^^^^^^^^
AttributeError: 'ConfigurationManager' object has no attribute 'get_data_ingestion_config'
[2025-06-20 00:00:07,194: INFO : common : Created directory at: artifacts]
[2025-06-20 00:00:07,215: INFO : main : >> stage Data Ingestion stage has started >>>>]
[2025-06-20 00:00:07,217: INFO : common : YML file: config/config.yaml loaded successfully]
[2025-06-20 00:00:07,218: INFO : common : YML file: params.yaml loaded successfully]
[2025-06-20 00:00:07,220: INFO : common : YML file: schema.yaml loaded successfully]
[2025-06-20 00:00:07,220: INFO : common : Created directory at: artifacts]
[2025-06-20 00:00:07,220: INFO : common : Created directory at: artifacts/data_ingestion]
[2025-06-20 00:00:07,221: INFO : data_ingestion : file already exists: 23 KB]
[2025-06-20 00:00:07,332: INFO : main : >>>> stage Data Ingestion stage completed >>>>>]
[2025-06-20 00:00:07,332: INFO : main : >> stage Data Validation stage has started >>>>]
[2025-06-20 00:00:07,335: INFO : common : YML file: config/config.yaml loaded successfully]
[2025-06-20 00:00:07,337: INFO : common : YML file: params.yaml loaded successfully]
[2025-06-20 00:00:07,341: INFO : common : YML file: schema.yaml loaded successfully]
[2025-06-20 00:00:07,342: INFO : common : Created directory at: artifacts]
[2025-06-20 00:00:07,343: ERROR : main : 'ValidationConfigurationManager' object has no attribute 'get_data_ingestion_config']
Traceback (most recent call last):
  File "/home/moses/Documents/machine_learning/End_to_end_ml_project/main.py", line 25, in <module>
    obj.main()
  File "/home/moses/Documents/machine_learning/End_to_end_ml_project/src/my_project/pipeline/validation_stage.py", line 13, in main
    data_validation_config = config.get_data_ingestion_config()
                             ^^^^^^^^^^^^^^^^^^^^^^^^^^^^^^^^
AttributeError: 'ValidationConfigurationManager' object has no attribute 'get_data_ingestion_config'
[2025-06-20 00:05:10,299: INFO : common : Created directory at: artifacts]
[2025-06-20 00:05:10,320: INFO : main : >> stage Data Ingestion stage has started >>>>]
[2025-06-20 00:05:10,323: INFO : common : YML file: config/config.yaml loaded successfully]
[2025-06-20 00:05:10,323: INFO : common : YML file: params.yaml loaded successfully]
[2025-06-20 00:05:10,325: INFO : common : YML file: schema.yaml loaded successfully]
[2025-06-20 00:05:10,326: INFO : common : Created directory at: artifacts]
[2025-06-20 00:05:10,326: INFO : common : Created directory at: artifacts/data_ingestion]
[2025-06-20 00:05:10,327: INFO : data_ingestion : file already exists: 23 KB]
[2025-06-20 00:05:10,329: INFO : main : >>>> stage Data Ingestion stage completed >>>>>]
[2025-06-20 00:05:10,329: INFO : main : >> stage Data Validation stage has started >>>>]
[2025-06-20 00:05:10,331: INFO : common : YML file: config/config.yaml loaded successfully]
[2025-06-20 00:05:10,332: INFO : common : YML file: params.yaml loaded successfully]
[2025-06-20 00:05:10,334: INFO : common : YML file: schema.yaml loaded successfully]
[2025-06-20 00:05:10,335: INFO : common : Created directory at: artifacts]
[2025-06-20 00:05:10,381: INFO : common : Created directory at: artifacts/data_validation]
[2025-06-20 00:05:10,381: ERROR : main : name 'pd' is not defined]
Traceback (most recent call last):
  File "/home/moses/Documents/machine_learning/End_to_end_ml_project/main.py", line 25, in <module>
    obj.main()
  File "/home/moses/Documents/machine_learning/End_to_end_ml_project/src/my_project/pipeline/validation_stage.py", line 15, in main
    data_validation.validate_all_columns()
  File "/home/moses/Documents/machine_learning/End_to_end_ml_project/src/my_project/Components/data_validation.py", line 35, in validate_all_columns
    raise e
  File "/home/moses/Documents/machine_learning/End_to_end_ml_project/src/my_project/Components/data_validation.py", line 17, in validate_all_columns
    data = pd.read_csv(self.config.unzip_data_dir)
           ^^
NameError: name 'pd' is not defined
[2025-06-20 00:06:25,875: INFO : common : Created directory at: artifacts]
[2025-06-20 00:06:31,413: INFO : utils : NumExpr defaulting to 2 threads.]
[2025-06-20 00:06:34,127: INFO : main : >> stage Data Ingestion stage has started >>>>]
[2025-06-20 00:06:34,131: INFO : common : YML file: config/config.yaml loaded successfully]
[2025-06-20 00:06:34,133: INFO : common : YML file: params.yaml loaded successfully]
[2025-06-20 00:06:34,136: INFO : common : YML file: schema.yaml loaded successfully]
[2025-06-20 00:06:34,137: INFO : common : Created directory at: artifacts]
[2025-06-20 00:06:34,138: INFO : common : Created directory at: artifacts/data_ingestion]
[2025-06-20 00:06:34,138: INFO : data_ingestion : file already exists: 23 KB]
[2025-06-20 00:06:34,142: INFO : main : >>>> stage Data Ingestion stage completed >>>>>]
[2025-06-20 00:06:34,142: INFO : main : >> stage Data Validation stage has started >>>>]
[2025-06-20 00:06:34,144: INFO : common : YML file: config/config.yaml loaded successfully]
[2025-06-20 00:06:34,145: INFO : common : YML file: params.yaml loaded successfully]
[2025-06-20 00:06:34,147: INFO : common : YML file: schema.yaml loaded successfully]
[2025-06-20 00:06:34,148: INFO : common : Created directory at: artifacts]
[2025-06-20 00:06:34,148: INFO : common : Created directory at: artifacts/data_validation]
[2025-06-20 00:06:34,148: ERROR : main : 'NoneType' object has no attribute 'unzip_data_dir']
Traceback (most recent call last):
  File "/home/moses/Documents/machine_learning/End_to_end_ml_project/main.py", line 25, in <module>
    obj.main()
  File "/home/moses/Documents/machine_learning/End_to_end_ml_project/src/my_project/pipeline/validation_stage.py", line 15, in main
    data_validation.validate_all_columns()
  File "/home/moses/Documents/machine_learning/End_to_end_ml_project/src/my_project/Components/data_validation.py", line 36, in validate_all_columns
    raise e
  File "/home/moses/Documents/machine_learning/End_to_end_ml_project/src/my_project/Components/data_validation.py", line 18, in validate_all_columns
    data = pd.read_csv(self.config.unzip_data_dir)
                       ^^^^^^^^^^^^^^^^^^^^^^^^^^
AttributeError: 'NoneType' object has no attribute 'unzip_data_dir'
[2025-06-20 00:07:10,236: INFO : common : Created directory at: artifacts]
[2025-06-20 00:07:10,477: INFO : utils : NumExpr defaulting to 2 threads.]
[2025-06-20 00:07:10,699: INFO : main : >> stage Data Ingestion stage has started >>>>]
[2025-06-20 00:07:10,702: INFO : common : YML file: config/config.yaml loaded successfully]
[2025-06-20 00:07:10,702: INFO : common : YML file: params.yaml loaded successfully]
[2025-06-20 00:07:10,705: INFO : common : YML file: schema.yaml loaded successfully]
[2025-06-20 00:07:10,705: INFO : common : Created directory at: artifacts]
[2025-06-20 00:07:10,706: INFO : common : Created directory at: artifacts/data_ingestion]
[2025-06-20 00:07:10,706: INFO : data_ingestion : file already exists: 23 KB]
[2025-06-20 00:07:10,708: INFO : main : >>>> stage Data Ingestion stage completed >>>>>]
[2025-06-20 00:07:10,708: INFO : main : >> stage Data Validation stage has started >>>>]
[2025-06-20 00:07:10,710: INFO : common : YML file: config/config.yaml loaded successfully]
[2025-06-20 00:07:10,711: INFO : common : YML file: params.yaml loaded successfully]
[2025-06-20 00:07:10,713: INFO : common : YML file: schema.yaml loaded successfully]
[2025-06-20 00:07:10,714: INFO : common : Created directory at: artifacts]
[2025-06-20 00:07:10,714: INFO : common : Created directory at: artifacts/data_validation]
[2025-06-20 00:07:10,714: ERROR : main : 'NoneType' object has no attribute 'unzip_dir']
Traceback (most recent call last):
  File "/home/moses/Documents/machine_learning/End_to_end_ml_project/main.py", line 25, in <module>
    obj.main()
  File "/home/moses/Documents/machine_learning/End_to_end_ml_project/src/my_project/pipeline/validation_stage.py", line 15, in main
    data_validation.validate_all_columns()
  File "/home/moses/Documents/machine_learning/End_to_end_ml_project/src/my_project/Components/data_validation.py", line 36, in validate_all_columns
    raise e
  File "/home/moses/Documents/machine_learning/End_to_end_ml_project/src/my_project/Components/data_validation.py", line 18, in validate_all_columns
    data = pd.read_csv(self.config.unzip_dir)
                       ^^^^^^^^^^^^^^^^^^^^^
AttributeError: 'NoneType' object has no attribute 'unzip_dir'
[2025-06-20 09:16:17,267: INFO : common : Created directory at: artifacts]
[2025-06-20 09:16:23,566: INFO : utils : NumExpr defaulting to 2 threads.]
[2025-06-20 09:16:26,627: INFO : main : >> stage Data Ingestion stage has started >>>>]
[2025-06-20 09:16:26,651: INFO : common : YML file: config/config.yaml loaded successfully]
[2025-06-20 09:16:26,653: INFO : common : YML file: params.yaml loaded successfully]
[2025-06-20 09:16:26,657: INFO : common : YML file: schema.yaml loaded successfully]
[2025-06-20 09:16:26,659: INFO : common : Created directory at: artifacts]
[2025-06-20 09:16:26,660: INFO : common : Created directory at: artifacts/data_ingestion]
[2025-06-20 09:16:26,660: INFO : data_ingestion : file already exists: 23 KB]
[2025-06-20 09:16:26,678: INFO : main : >>>> stage Data Ingestion stage completed >>>>>]
[2025-06-20 09:16:26,678: INFO : main : >> stage Data Validation stage has started >>>>]
[2025-06-20 09:16:26,683: INFO : common : YML file: config/config.yaml loaded successfully]
[2025-06-20 09:16:26,684: INFO : common : YML file: params.yaml loaded successfully]
[2025-06-20 09:16:26,686: INFO : common : YML file: schema.yaml loaded successfully]
[2025-06-20 09:16:26,687: INFO : common : Created directory at: artifacts]
[2025-06-20 09:16:26,687: INFO : common : Created directory at: artifacts/data_validation]
[2025-06-20 09:16:26,687: ERROR : main : 'NoneType' object has no attribute 'unzip_dir']
Traceback (most recent call last):
  File "/home/moses/Documents/machine_learning/End_to_end_ml_project/main.py", line 25, in <module>
    obj.main()
  File "/home/moses/Documents/machine_learning/End_to_end_ml_project/src/my_project/pipeline/validation_stage.py", line 15, in main
    data_validation.validate_all_columns()
  File "/home/moses/Documents/machine_learning/End_to_end_ml_project/src/my_project/Components/data_validation.py", line 36, in validate_all_columns
    raise e
  File "/home/moses/Documents/machine_learning/End_to_end_ml_project/src/my_project/Components/data_validation.py", line 18, in validate_all_columns
    data = pd.read_csv(self.config.unzip_dir)
                       ^^^^^^^^^^^^^^^^^^^^^
AttributeError: 'NoneType' object has no attribute 'unzip_dir'
[2025-06-20 09:35:57,240: INFO : common : Created directory at: artifacts]
[2025-06-20 09:35:58,516: INFO : utils : NumExpr defaulting to 2 threads.]
[2025-06-20 09:35:59,333: INFO : main : >> stage Data Ingestion stage has started >>>>]
[2025-06-20 09:35:59,335: INFO : common : YML file: config/config.yaml loaded successfully]
[2025-06-20 09:35:59,336: INFO : common : YML file: params.yaml loaded successfully]
[2025-06-20 09:35:59,339: INFO : common : YML file: schema.yaml loaded successfully]
[2025-06-20 09:35:59,339: INFO : common : Created directory at: artifacts]
[2025-06-20 09:35:59,339: INFO : common : Created directory at: artifacts/data_ingestion]
[2025-06-20 09:35:59,340: INFO : data_ingestion : file already exists: 23 KB]
[2025-06-20 09:35:59,358: INFO : main : >>>> stage Data Ingestion stage completed >>>>>]
[2025-06-20 09:35:59,358: INFO : main : >> stage Data Validation stage has started >>>>]
[2025-06-20 09:35:59,360: INFO : common : YML file: config/config.yaml loaded successfully]
[2025-06-20 09:35:59,361: INFO : common : YML file: params.yaml loaded successfully]
[2025-06-20 09:35:59,363: INFO : common : YML file: schema.yaml loaded successfully]
[2025-06-20 09:35:59,363: INFO : common : Created directory at: artifacts]
[2025-06-20 09:35:59,363: INFO : common : Created directory at: artifacts/data_validation]
[2025-06-20 09:35:59,363: ERROR : main : 'NoneType' object has no attribute 'unzip_dir']
Traceback (most recent call last):
  File "/home/moses/Documents/machine_learning/End_to_end_ml_project/main.py", line 25, in <module>
    obj.main()
  File "/home/moses/Documents/machine_learning/End_to_end_ml_project/src/my_project/pipeline/validation_stage.py", line 17, in main
    data_validation.validate_all_columns()
  File "/home/moses/Documents/machine_learning/End_to_end_ml_project/src/my_project/Components/data_validation.py", line 36, in validate_all_columns
    raise e
  File "/home/moses/Documents/machine_learning/End_to_end_ml_project/src/my_project/Components/data_validation.py", line 18, in validate_all_columns
    data = pd.read_csv(self.config.unzip_dir)
                       ^^^^^^^^^^^^^^^^^^^^^
AttributeError: 'NoneType' object has no attribute 'unzip_dir'
[2025-06-20 10:46:44,419: INFO : common : Created directory at: artifacts]
[2025-06-20 10:46:44,664: INFO : utils : NumExpr defaulting to 2 threads.]
[2025-06-20 10:46:44,890: INFO : main : >> stage Data Ingestion stage has started >>>>]
[2025-06-20 10:46:44,893: INFO : common : YML file: config/config.yaml loaded successfully]
[2025-06-20 10:46:44,895: INFO : common : YML file: params.yaml loaded successfully]
[2025-06-20 10:46:44,897: INFO : common : YML file: schema.yaml loaded successfully]
[2025-06-20 10:46:44,897: INFO : common : Created directory at: artifacts]
[2025-06-20 10:46:44,898: INFO : common : Created directory at: artifacts/data_ingestion]
[2025-06-20 10:46:44,898: INFO : data_ingestion : file already exists: 23 KB]
[2025-06-20 10:46:44,900: INFO : main : >>>> stage Data Ingestion stage completed >>>>>]
[2025-06-20 10:46:44,901: INFO : main : >> stage Data Validation stage has started >>>>]
[2025-06-20 10:46:44,902: INFO : common : YML file: config/config.yaml loaded successfully]
[2025-06-20 10:46:44,903: INFO : common : YML file: params.yaml loaded successfully]
[2025-06-20 10:46:44,905: INFO : common : YML file: schema.yaml loaded successfully]
[2025-06-20 10:46:44,906: INFO : common : Created directory at: artifacts]
[2025-06-20 10:46:44,906: INFO : common : Created directory at: artifacts/data_validation]
[2025-06-20 10:46:44,906: ERROR : main : 'NoneType' object has no attribute 'unzip_dir']
Traceback (most recent call last):
  File "/home/moses/Documents/machine_learning/End_to_end_ml_project/main.py", line 25, in <module>
    obj.main()
  File "/home/moses/Documents/machine_learning/End_to_end_ml_project/src/my_project/pipeline/validation_stage.py", line 17, in main
    data_validation.validate_all_columns()
  File "/home/moses/Documents/machine_learning/End_to_end_ml_project/src/my_project/Components/data_validation.py", line 36, in validate_all_columns
    raise e
  File "/home/moses/Documents/machine_learning/End_to_end_ml_project/src/my_project/Components/data_validation.py", line 18, in validate_all_columns
    data = pd.read_csv(self.config.unzip_dir)
                       ^^^^^^^^^^^^^^^^^^^^^
AttributeError: 'NoneType' object has no attribute 'unzip_dir'
[2025-06-20 10:51:21,931: INFO : common : Created directory at: artifacts]
[2025-06-20 10:51:24,495: INFO : utils : NumExpr defaulting to 2 threads.]
[2025-06-20 10:51:26,457: INFO : main : >> stage Data Ingestion stage has started >>>>]
[2025-06-20 10:51:26,462: INFO : common : YML file: config/config.yaml loaded successfully]
[2025-06-20 10:51:26,463: INFO : common : YML file: params.yaml loaded successfully]
[2025-06-20 10:51:26,466: INFO : common : YML file: schema.yaml loaded successfully]
[2025-06-20 10:51:26,466: INFO : common : Created directory at: artifacts]
[2025-06-20 10:51:26,467: INFO : common : Created directory at: artifacts/data_ingestion]
[2025-06-20 10:51:26,467: INFO : data_ingestion : file already exists: 23 KB]
[2025-06-20 10:51:26,482: INFO : main : >>>> stage Data Ingestion stage completed >>>>>]
[2025-06-20 10:51:26,482: INFO : main : >> stage Data Validation stage has started >>>>]
[2025-06-20 10:51:26,484: INFO : common : YML file: config/config.yaml loaded successfully]
[2025-06-20 10:51:26,484: INFO : common : YML file: params.yaml loaded successfully]
[2025-06-20 10:51:26,486: INFO : common : YML file: schema.yaml loaded successfully]
[2025-06-20 10:51:26,487: INFO : common : Created directory at: artifacts]
[2025-06-20 10:51:26,487: INFO : common : Created directory at: artifacts/data_validation]
[2025-06-20 10:51:26,487: ERROR : main : 'NoneType' object has no attribute 'unzip_dir']
Traceback (most recent call last):
  File "/home/moses/Documents/machine_learning/End_to_end_ml_project/main.py", line 25, in <module>
    obj.main()
  File "/home/moses/Documents/machine_learning/End_to_end_ml_project/src/my_project/pipeline/validation_stage.py", line 17, in main
    data_validation.validate_all_columns()
  File "/home/moses/Documents/machine_learning/End_to_end_ml_project/src/my_project/Components/data_validation.py", line 36, in validate_all_columns
    raise e
  File "/home/moses/Documents/machine_learning/End_to_end_ml_project/src/my_project/Components/data_validation.py", line 18, in validate_all_columns
    data = pd.read_csv(self.config.unzip_dir)
                       ^^^^^^^^^^^^^^^^^^^^^
AttributeError: 'NoneType' object has no attribute 'unzip_dir'
[2025-06-29 09:29:41,919: INFO : common : Created directory at: artifacts]
[2025-06-29 09:29:50,443: INFO : utils : NumExpr defaulting to 2 threads.]
[2025-06-29 09:29:55,335: INFO : main : >> stage Data Ingestion stage has started >>>>]
[2025-06-29 09:29:55,386: INFO : common : YML file: config/config.yaml loaded successfully]
[2025-06-29 09:29:55,420: INFO : common : YML file: params.yaml loaded successfully]
[2025-06-29 09:29:55,431: INFO : common : YML file: schema.yaml loaded successfully]
[2025-06-29 09:29:55,439: INFO : common : Created directory at: artifacts]
[2025-06-29 09:29:55,477: INFO : common : Created directory at: artifacts/data_ingestion]
[2025-06-29 09:29:55,479: INFO : data_ingestion : file already exists: 23 KB]
[2025-06-29 09:29:55,516: INFO : main : >>>> stage Data Ingestion stage completed >>>>>]
[2025-06-29 09:29:55,522: INFO : main : >> stage Data Validation stage has started >>>>]
[2025-06-29 09:29:55,527: INFO : common : YML file: config/config.yaml loaded successfully]
[2025-06-29 09:29:55,557: INFO : common : YML file: params.yaml loaded successfully]
[2025-06-29 09:29:55,575: INFO : common : YML file: schema.yaml loaded successfully]
[2025-06-29 09:29:55,584: INFO : common : Created directory at: artifacts]
[2025-06-29 09:29:55,585: INFO : common : Created directory at: artifacts/data_validation]
[2025-06-29 09:29:55,586: ERROR : main : 'NoneType' object has no attribute 'unzip_dir']
Traceback (most recent call last):
  File "/home/moses/Documents/machine_learning/End_to_end_ml_project/main.py", line 25, in <module>
    obj.main()
  File "/home/moses/Documents/machine_learning/End_to_end_ml_project/src/my_project/pipeline/validation_stage.py", line 17, in main
    data_validation.validate_all_columns()
  File "/home/moses/Documents/machine_learning/End_to_end_ml_project/src/my_project/Components/data_validation.py", line 36, in validate_all_columns
    raise e
  File "/home/moses/Documents/machine_learning/End_to_end_ml_project/src/my_project/Components/data_validation.py", line 18, in validate_all_columns
    data = pd.read_csv(self.config.unzip_dir)
                       ^^^^^^^^^^^^^^^^^^^^^
AttributeError: 'NoneType' object has no attribute 'unzip_dir'
[2025-06-29 09:50:37,373: INFO : common : Created directory at: artifacts]
[2025-06-29 09:50:40,711: INFO : utils : NumExpr defaulting to 2 threads.]
[2025-06-29 09:50:43,593: INFO : main : >> stage Data Ingestion stage has started >>>>]
[2025-06-29 09:50:43,598: INFO : common : YML file: config/config.yaml loaded successfully]
[2025-06-29 09:50:43,601: INFO : common : YML file: params.yaml loaded successfully]
[2025-06-29 09:50:43,606: INFO : common : YML file: schema.yaml loaded successfully]
[2025-06-29 09:50:43,607: INFO : common : Created directory at: artifacts]
[2025-06-29 09:50:43,607: INFO : common : Created directory at: artifacts/data_ingestion]
[2025-06-29 09:50:43,608: INFO : data_ingestion : file already exists: 23 KB]
[2025-06-29 09:50:43,653: INFO : main : >>>> stage Data Ingestion stage completed >>>>>]
[2025-06-29 09:50:43,653: INFO : main : >> stage Data Validation stage has started >>>>]
[2025-06-29 09:50:43,655: INFO : common : YML file: config/config.yaml loaded successfully]
[2025-06-29 09:50:43,658: INFO : common : YML file: params.yaml loaded successfully]
[2025-06-29 09:50:43,661: INFO : common : YML file: schema.yaml loaded successfully]
[2025-06-29 09:50:43,662: INFO : common : Created directory at: artifacts]
[2025-06-29 09:50:43,662: INFO : common : Created directory at: artifacts/data_validation]
[2025-06-29 09:50:43,663: ERROR : main : 'NoneType' object has no attribute 'unzip_dir']
Traceback (most recent call last):
  File "/home/moses/Documents/machine_learning/End_to_end_ml_project/main.py", line 25, in <module>
    obj.main()
  File "/home/moses/Documents/machine_learning/End_to_end_ml_project/src/my_project/pipeline/validation_stage.py", line 17, in main
    data_validation.validate_all_columns()
  File "/home/moses/Documents/machine_learning/End_to_end_ml_project/src/my_project/Components/data_validation.py", line 36, in validate_all_columns
    raise e
  File "/home/moses/Documents/machine_learning/End_to_end_ml_project/src/my_project/Components/data_validation.py", line 18, in validate_all_columns
    data = pd.read_csv(self.config.unzip_dir)
                       ^^^^^^^^^^^^^^^^^^^^^
AttributeError: 'NoneType' object has no attribute 'unzip_dir'
[2025-06-29 09:51:02,749: INFO : common : Created directory at: artifacts]
[2025-06-29 09:51:02,998: INFO : utils : NumExpr defaulting to 2 threads.]
[2025-06-29 09:51:03,284: INFO : main : >> stage Data Ingestion stage has started >>>>]
[2025-06-29 09:51:03,290: INFO : common : YML file: config/config.yaml loaded successfully]
[2025-06-29 09:51:03,296: INFO : common : YML file: params.yaml loaded successfully]
[2025-06-29 09:51:03,299: INFO : common : YML file: schema.yaml loaded successfully]
[2025-06-29 09:51:03,304: INFO : common : Created directory at: artifacts]
[2025-06-29 09:51:03,305: INFO : common : Created directory at: artifacts/data_ingestion]
[2025-06-29 09:51:03,305: INFO : data_ingestion : file already exists: 23 KB]
[2025-06-29 09:51:03,310: INFO : main : >>>> stage Data Ingestion stage completed >>>>>]
[2025-06-29 09:51:03,311: INFO : main : >> stage Data Validation stage has started >>>>]
[2025-06-29 09:51:03,313: INFO : common : YML file: config/config.yaml loaded successfully]
[2025-06-29 09:51:03,314: INFO : common : YML file: params.yaml loaded successfully]
[2025-06-29 09:51:03,317: INFO : common : YML file: schema.yaml loaded successfully]
[2025-06-29 09:51:03,319: INFO : common : Created directory at: artifacts]
[2025-06-29 09:51:03,320: INFO : common : Created directory at: artifacts/data_validation]
[2025-06-29 09:51:03,320: ERROR : main : 'NoneType' object has no attribute 'unzip_dir']
Traceback (most recent call last):
  File "/home/moses/Documents/machine_learning/End_to_end_ml_project/main.py", line 25, in <module>
    obj.main()
  File "/home/moses/Documents/machine_learning/End_to_end_ml_project/src/my_project/pipeline/validation_stage.py", line 17, in main
    data_validation.validate_all_columns()
  File "/home/moses/Documents/machine_learning/End_to_end_ml_project/src/my_project/Components/data_validation.py", line 36, in validate_all_columns
    raise e
  File "/home/moses/Documents/machine_learning/End_to_end_ml_project/src/my_project/Components/data_validation.py", line 18, in validate_all_columns
    data = pd.read_csv(self.config.unzip_dir)
                       ^^^^^^^^^^^^^^^^^^^^^
AttributeError: 'NoneType' object has no attribute 'unzip_dir'
[2025-06-29 09:54:08,861: INFO : common : Created directory at: artifacts]
[2025-06-29 09:55:20,211: INFO : common : Created directory at: artifacts]
[2025-06-29 09:56:52,904: INFO : common : Created directory at: artifacts]
[2025-06-29 09:56:57,093: INFO : utils : NumExpr defaulting to 2 threads.]
[2025-06-29 09:56:57,858: INFO : main : >> stage Data Ingestion stage has started >>>>]
[2025-06-29 09:56:57,861: INFO : common : YML file: config/config.yaml loaded successfully]
[2025-06-29 09:56:57,862: INFO : common : YML file: params.yaml loaded successfully]
[2025-06-29 09:56:57,866: INFO : common : YML file: schema.yaml loaded successfully]
[2025-06-29 09:56:57,867: INFO : common : Created directory at: artifacts]
[2025-06-29 09:56:57,868: INFO : common : Created directory at: artifacts/data_ingestion]
[2025-06-29 09:56:57,869: INFO : data_ingestion : file already exists: 23 KB]
[2025-06-29 09:56:57,871: INFO : main : >>>> stage Data Ingestion stage completed >>>>>]
[2025-06-29 09:56:57,871: INFO : main : >> stage Data Validation stage has started >>>>]
[2025-06-29 09:56:57,873: INFO : common : YML file: config/config.yaml loaded successfully]
[2025-06-29 09:56:57,874: INFO : common : YML file: params.yaml loaded successfully]
[2025-06-29 09:56:57,876: INFO : common : YML file: schema.yaml loaded successfully]
[2025-06-29 09:56:57,877: INFO : common : Created directory at: artifacts]
[2025-06-29 09:56:57,877: INFO : common : Created directory at: artifacts/data_validation]
[2025-06-29 09:56:57,877: ERROR : main : 'NoneType' object has no attribute 'get']
Traceback (most recent call last):
  File "/home/moses/Documents/machine_learning/End_to_end_ml_project/main.py", line 25, in <module>
    obj.main()
  File "/home/moses/Documents/machine_learning/End_to_end_ml_project/src/my_project/pipeline/validation_stage.py", line 16, in main
    data_validation = DataValidation(config=data_validation_config)
                      ^^^^^^^^^^^^^^^^^^^^^^^^^^^^^^^^^^^^^^^^^^^^^
  File "/home/moses/Documents/machine_learning/End_to_end_ml_project/src/my_project/Components/data_validation.py", line 14, in __init__
    print(self.config.get('data_validation'))
          ^^^^^^^^^^^^^^^
AttributeError: 'NoneType' object has no attribute 'get'
[2025-06-29 09:58:26,515: INFO : common : Created directory at: artifacts]
[2025-06-29 09:58:26,778: INFO : utils : NumExpr defaulting to 2 threads.]
[2025-06-29 09:58:27,013: INFO : main : >> stage Data Ingestion stage has started >>>>]
[2025-06-29 09:58:27,018: INFO : common : YML file: config/config.yaml loaded successfully]
[2025-06-29 09:58:27,019: INFO : common : YML file: params.yaml loaded successfully]
[2025-06-29 09:58:27,023: INFO : common : YML file: schema.yaml loaded successfully]
[2025-06-29 09:58:27,023: INFO : common : Created directory at: artifacts]
[2025-06-29 09:58:27,024: INFO : common : Created directory at: artifacts/data_ingestion]
[2025-06-29 09:58:27,024: INFO : data_ingestion : file already exists: 23 KB]
[2025-06-29 09:58:27,027: INFO : main : >>>> stage Data Ingestion stage completed >>>>>]
[2025-06-29 09:58:27,027: INFO : main : >> stage Data Validation stage has started >>>>]
[2025-06-29 09:58:27,029: INFO : common : YML file: config/config.yaml loaded successfully]
[2025-06-29 09:58:27,031: INFO : common : YML file: params.yaml loaded successfully]
[2025-06-29 09:58:27,034: INFO : common : YML file: schema.yaml loaded successfully]
[2025-06-29 09:58:27,034: INFO : common : Created directory at: artifacts]
[2025-06-29 09:58:27,035: INFO : common : Created directory at: artifacts/data_validation]
[2025-06-29 09:58:27,035: ERROR : main : 'NoneType' object has no attribute 'unzip_dir']
Traceback (most recent call last):
  File "/home/moses/Documents/machine_learning/End_to_end_ml_project/main.py", line 25, in <module>
    obj.main()
  File "/home/moses/Documents/machine_learning/End_to_end_ml_project/src/my_project/pipeline/validation_stage.py", line 16, in main
    data_validation = DataValidation(config=data_validation_config)
                      ^^^^^^^^^^^^^^^^^^^^^^^^^^^^^^^^^^^^^^^^^^^^^
  File "/home/moses/Documents/machine_learning/End_to_end_ml_project/src/my_project/Components/data_validation.py", line 14, in __init__
    print(self.config.unzip_dir)
          ^^^^^^^^^^^^^^^^^^^^^
AttributeError: 'NoneType' object has no attribute 'unzip_dir'
[2025-06-30 22:28:24,701: INFO : common : Created directory at: artifacts]
[2025-06-30 22:28:31,679: INFO : utils : NumExpr defaulting to 2 threads.]
[2025-06-30 22:28:34,426: INFO : main : >> stage Data Ingestion stage has started >>>>]
[2025-06-30 22:28:34,441: INFO : common : YML file: config/config.yaml loaded successfully]
[2025-06-30 22:28:34,465: INFO : common : YML file: params.yaml loaded successfully]
[2025-06-30 22:28:34,472: INFO : common : YML file: schema.yaml loaded successfully]
[2025-06-30 22:28:34,473: INFO : common : Created directory at: artifacts]
[2025-06-30 22:28:34,475: INFO : common : Created directory at: artifacts/data_ingestion]
[2025-06-30 22:28:34,476: INFO : data_ingestion : file already exists: 23 KB]
[2025-06-30 22:28:34,511: INFO : main : >>>> stage Data Ingestion stage completed >>>>>]
[2025-06-30 22:28:34,511: INFO : main : >> stage Data Validation stage has started >>>>]
[2025-06-30 22:28:34,514: INFO : common : YML file: config/config.yaml loaded successfully]
[2025-06-30 22:28:34,515: INFO : common : YML file: params.yaml loaded successfully]
[2025-06-30 22:28:34,518: INFO : common : YML file: schema.yaml loaded successfully]
[2025-06-30 22:28:34,519: INFO : common : Created directory at: artifacts]
[2025-06-30 22:28:34,519: INFO : common : Created directory at: artifacts/data_validation]
[2025-06-30 22:28:34,519: ERROR : main : 'NoneType' object has no attribute 'unzip_dir']
Traceback (most recent call last):
  File "/home/moses/Documents/machine_learning/End_to_end_ml_project/main.py", line 25, in <module>
    obj.main()
  File "/home/moses/Documents/machine_learning/End_to_end_ml_project/src/my_project/pipeline/validation_stage.py", line 16, in main
    data_validation = DataValidation(config=data_validation_config)
                      ^^^^^^^^^^^^^^^^^^^^^^^^^^^^^^^^^^^^^^^^^^^^^
  File "/home/moses/Documents/machine_learning/End_to_end_ml_project/src/my_project/Components/data_validation.py", line 14, in __init__
    print(self.config.unzip_dir)
          ^^^^^^^^^^^^^^^^^^^^^
AttributeError: 'NoneType' object has no attribute 'unzip_dir'
[2025-07-01 00:43:11,555: INFO : common : Created directory at: artifacts]
[2025-07-01 00:43:17,595: INFO : utils : NumExpr defaulting to 2 threads.]
[2025-07-01 00:43:20,113: INFO : main : >> stage Data Ingestion stage has started >>>>]
[2025-07-01 00:43:20,128: INFO : common : YML file: config/config.yaml loaded successfully]
[2025-07-01 00:43:20,129: INFO : common : YML file: params.yaml loaded successfully]
[2025-07-01 00:43:20,131: INFO : common : YML file: schema.yaml loaded successfully]
[2025-07-01 00:43:20,131: INFO : common : Created directory at: artifacts]
[2025-07-01 00:43:20,132: INFO : common : Created directory at: artifacts/data_ingestion]
[2025-07-01 00:43:20,132: INFO : data_ingestion : file already exists: 23 KB]
[2025-07-01 00:43:20,152: INFO : main : >>>> stage Data Ingestion stage completed >>>>>]
[2025-07-01 00:43:20,152: INFO : main : >> stage Data Validation stage has started >>>>]
[2025-07-01 00:43:20,154: INFO : common : YML file: config/config.yaml loaded successfully]
[2025-07-01 00:43:20,155: INFO : common : YML file: params.yaml loaded successfully]
[2025-07-01 00:43:20,157: INFO : common : YML file: schema.yaml loaded successfully]
[2025-07-01 00:43:20,158: INFO : common : Created directory at: artifacts]
[2025-07-01 00:43:20,158: INFO : common : Created directory at: artifacts/data_validation]
[2025-07-01 00:43:20,359: INFO : main : >>>> stage Data Validation stage completed >>>>>]
[2025-07-01 00:47:52,141: INFO : common : Created directory at: artifacts]
[2025-07-01 00:47:52,507: INFO : utils : NumExpr defaulting to 2 threads.]
[2025-07-01 00:47:53,101: INFO : main : >> stage Data Ingestion stage has started >>>>]
[2025-07-01 00:47:53,104: INFO : common : YML file: config/config.yaml loaded successfully]
[2025-07-01 00:47:53,106: INFO : common : YML file: params.yaml loaded successfully]
[2025-07-01 00:47:53,110: INFO : common : YML file: schema.yaml loaded successfully]
[2025-07-01 00:47:53,110: INFO : common : Created directory at: artifacts]
[2025-07-01 00:47:53,111: INFO : common : Created directory at: artifacts/data_ingestion]
[2025-07-01 00:47:53,112: INFO : data_ingestion : file already exists: 23 KB]
[2025-07-01 00:47:53,114: INFO : main : >>>> stage Data Ingestion stage completed >>>>>]
[2025-07-01 00:47:53,114: INFO : main : >> stage Data Validation stage has started >>>>]
[2025-07-01 00:47:53,116: INFO : common : YML file: config/config.yaml loaded successfully]
[2025-07-01 00:47:53,117: INFO : common : YML file: params.yaml loaded successfully]
[2025-07-01 00:47:53,120: INFO : common : YML file: schema.yaml loaded successfully]
[2025-07-01 00:47:53,121: INFO : common : Created directory at: artifacts]
[2025-07-01 00:47:53,121: INFO : common : Created directory at: artifacts/data_validation]
[2025-07-01 00:47:53,136: INFO : main : >>>> stage Data Validation stage completed >>>>>]
[2025-07-02 07:58:05,183: INFO : utils : NumExpr defaulting to 2 threads.]
[2025-07-02 08:03:43,454: INFO : utils : NumExpr defaulting to 2 threads.]
[2025-07-02 08:06:21,899: INFO : utils : NumExpr defaulting to 2 threads.]
[2025-07-02 08:12:24,763: INFO : utils : NumExpr defaulting to 2 threads.]
[2025-07-02 08:12:25,133: INFO : common : Created directory at: artifacts]
[2025-07-02 08:14:24,297: INFO : utils : NumExpr defaulting to 2 threads.]
[2025-07-02 08:14:24,740: INFO : common : Created directory at: artifacts]
[2025-07-02 08:15:27,687: INFO : utils : NumExpr defaulting to 2 threads.]
[2025-07-02 08:15:27,933: INFO : common : Created directory at: artifacts]
[2025-07-02 08:16:03,575: INFO : utils : NumExpr defaulting to 2 threads.]
[2025-07-02 08:16:03,817: INFO : common : Created directory at: artifacts]
[2025-07-02 08:19:48,592: INFO : utils : NumExpr defaulting to 2 threads.]
[2025-07-02 08:19:48,834: INFO : common : Created directory at: artifacts]
[2025-07-02 08:19:48,881: INFO : main : >> stage Data Ingestion stage has started >>>>]
[2025-07-02 08:19:48,925: INFO : common : YML file: config/config.yaml loaded successfully]
[2025-07-02 08:19:48,926: INFO : common : YML file: params.yaml loaded successfully]
[2025-07-02 08:19:48,930: INFO : common : YML file: schema.yaml loaded successfully]
[2025-07-02 08:19:48,931: INFO : common : Created directory at: artifacts]
[2025-07-02 08:19:48,931: INFO : common : Created directory at: artifacts/data_ingestion]
[2025-07-02 08:19:48,932: INFO : data_ingestion : file already exists: 23 KB]
[2025-07-02 08:19:48,961: INFO : main : >>>> stage Data Ingestion stage completed >>>>>]
[2025-07-02 08:19:48,963: INFO : main : >> stage Data Validation stage has started >>>>]
[2025-07-02 08:19:48,966: INFO : common : YML file: config/config.yaml loaded successfully]
[2025-07-02 08:19:48,967: INFO : common : YML file: params.yaml loaded successfully]
[2025-07-02 08:19:48,970: INFO : common : YML file: schema.yaml loaded successfully]
[2025-07-02 08:19:48,970: INFO : common : Created directory at: artifacts]
[2025-07-02 08:19:48,970: INFO : common : Created directory at: artifacts/data_validation]
[2025-07-02 08:19:48,982: INFO : main : >>>> stage Data Validation stage completed >>>>>]
[2025-07-02 08:19:48,982: INFO : main : >> stage Data Transformation stage has started >>>>]
[2025-07-02 08:19:48,984: INFO : common : YML file: config/config.yaml loaded successfully]
[2025-07-02 08:19:48,985: INFO : common : YML file: params.yaml loaded successfully]
[2025-07-02 08:19:48,988: INFO : common : YML file: schema.yaml loaded successfully]
[2025-07-02 08:19:48,989: INFO : common : Created directory at: artifacts]
[2025-07-02 08:19:48,989: INFO : common : Created directory at: artifacts/data_transformation]
[2025-07-02 08:19:48,989: ERROR : main : name 'BASE_DIR' is not defined]
Traceback (most recent call last):
  File "/home/moses/Documents/machine_learning/End_to_end_ml_project/main.py", line 23, in <module>
    obj.main()
  File "/home/moses/Documents/machine_learning/End_to_end_ml_project/src/my_project/pipeline/transformation_stage.py", line 13, in main
    data_transformation_config = config.get_data_transformation_config()
                                 ^^^^^^^^^^^^^^^^^^^^^^^^^^^^^^^^^^^^^^^
  File "/home/moses/Documents/machine_learning/End_to_end_ml_project/src/my_project/config/configuration.py", line 87, in get_data_transformation_config
    root_dir=Path(BASE_DIR) / "artifacts" / "data_transformation",
                  ^^^^^^^^
NameError: name 'BASE_DIR' is not defined
[2025-07-02 08:22:52,433: INFO : utils : NumExpr defaulting to 2 threads.]
[2025-07-02 08:22:52,780: INFO : common : Created directory at: artifacts]
[2025-07-02 08:22:52,843: INFO : main : >> stage Data Ingestion stage has started >>>>]
[2025-07-02 08:22:52,846: INFO : common : YML file: config/config.yaml loaded successfully]
[2025-07-02 08:22:52,847: INFO : common : YML file: params.yaml loaded successfully]
[2025-07-02 08:22:52,851: INFO : common : YML file: schema.yaml loaded successfully]
[2025-07-02 08:22:52,859: INFO : common : Created directory at: artifacts]
[2025-07-02 08:22:52,859: INFO : common : Created directory at: artifacts/data_ingestion]
[2025-07-02 08:22:52,860: INFO : data_ingestion : file already exists: 23 KB]
[2025-07-02 08:22:52,866: INFO : main : >>>> stage Data Ingestion stage completed >>>>>]
[2025-07-02 08:22:52,870: INFO : main : >> stage Data Validation stage has started >>>>]
[2025-07-02 08:22:52,878: INFO : common : YML file: config/config.yaml loaded successfully]
[2025-07-02 08:22:52,879: INFO : common : YML file: params.yaml loaded successfully]
[2025-07-02 08:22:52,891: INFO : common : YML file: schema.yaml loaded successfully]
[2025-07-02 08:22:52,892: INFO : common : Created directory at: artifacts]
[2025-07-02 08:22:52,892: INFO : common : Created directory at: artifacts/data_validation]
[2025-07-02 08:22:52,984: INFO : main : >>>> stage Data Validation stage completed >>>>>]
[2025-07-02 08:22:52,984: INFO : main : >> stage Data Transformation stage has started >>>>]
[2025-07-02 08:22:52,993: INFO : common : YML file: config/config.yaml loaded successfully]
[2025-07-02 08:22:52,999: INFO : common : YML file: params.yaml loaded successfully]
[2025-07-02 08:22:53,004: INFO : common : YML file: schema.yaml loaded successfully]
[2025-07-02 08:22:53,005: INFO : common : Created directory at: artifacts]
[2025-07-02 08:22:53,005: INFO : common : Created directory at: artifacts/data_transformation]
[2025-07-02 08:22:53,005: ERROR : main : name 'file_path' is not defined]
Traceback (most recent call last):
  File "/home/moses/Documents/machine_learning/End_to_end_ml_project/main.py", line 23, in <module>
    obj.main()
  File "/home/moses/Documents/machine_learning/End_to_end_ml_project/src/my_project/pipeline/transformation_stage.py", line 13, in main
    data_transformation_config = config.get_data_transformation_config()
                                 ^^^^^^^^^^^^^^^^^^^^^^^^^^^^^^^^^^^^^^^
  File "/home/moses/Documents/machine_learning/End_to_end_ml_project/src/my_project/config/configuration.py", line 92, in get_data_transformation_config
    data_path=Path(file_path)
                   ^^^^^^^^^
NameError: name 'file_path' is not defined
[2025-07-02 08:26:08,418: INFO : utils : NumExpr defaulting to 2 threads.]
[2025-07-02 08:26:08,676: INFO : common : Created directory at: artifacts]
[2025-07-02 08:26:08,694: INFO : main : >> stage Data Ingestion stage has started >>>>]
[2025-07-02 08:26:08,696: INFO : common : YML file: config/config.yaml loaded successfully]
[2025-07-02 08:26:08,697: INFO : common : YML file: params.yaml loaded successfully]
[2025-07-02 08:26:08,700: INFO : common : YML file: schema.yaml loaded successfully]
[2025-07-02 08:26:08,700: INFO : common : Created directory at: artifacts]
[2025-07-02 08:26:08,700: INFO : common : Created directory at: artifacts/data_ingestion]
[2025-07-02 08:26:08,701: INFO : data_ingestion : file already exists: 23 KB]
[2025-07-02 08:26:08,703: INFO : main : >>>> stage Data Ingestion stage completed >>>>>]
[2025-07-02 08:26:08,703: INFO : main : >> stage Data Validation stage has started >>>>]
[2025-07-02 08:26:08,705: INFO : common : YML file: config/config.yaml loaded successfully]
[2025-07-02 08:26:08,706: INFO : common : YML file: params.yaml loaded successfully]
[2025-07-02 08:26:08,708: INFO : common : YML file: schema.yaml loaded successfully]
[2025-07-02 08:26:08,709: INFO : common : Created directory at: artifacts]
[2025-07-02 08:26:08,709: INFO : common : Created directory at: artifacts/data_validation]
[2025-07-02 08:26:08,718: INFO : main : >>>> stage Data Validation stage completed >>>>>]
[2025-07-02 08:26:08,718: INFO : main : >> stage Data Transformation stage has started >>>>]
[2025-07-02 08:26:08,722: INFO : common : YML file: config/config.yaml loaded successfully]
[2025-07-02 08:26:08,723: INFO : common : YML file: params.yaml loaded successfully]
[2025-07-02 08:26:08,726: INFO : common : YML file: schema.yaml loaded successfully]
[2025-07-02 08:26:08,727: INFO : common : Created directory at: artifacts]
[2025-07-02 08:26:08,728: INFO : common : Created directory at: artifacts/data_transformation]
[2025-07-02 08:26:08,739: ERROR : main : name 'train_test_split' is not defined]
Traceback (most recent call last):
  File "/home/moses/Documents/machine_learning/End_to_end_ml_project/main.py", line 23, in <module>
    obj.main()
  File "/home/moses/Documents/machine_learning/End_to_end_ml_project/src/my_project/pipeline/transformation_stage.py", line 15, in main
    data_transformation.training_test_split()
  File "/home/moses/Documents/machine_learning/End_to_end_ml_project/src/my_project/Components/data_transformation.py", line 22, in training_test_split
    train, test = train_test_split(data)
                  ^^^^^^^^^^^^^^^^
NameError: name 'train_test_split' is not defined
[2025-07-02 08:27:48,066: INFO : utils : NumExpr defaulting to 2 threads.]
[2025-07-02 08:27:48,307: INFO : common : Created directory at: artifacts]
[2025-07-02 08:27:58,671: INFO : main : >> stage Data Ingestion stage has started >>>>]
[2025-07-02 08:27:58,676: INFO : common : YML file: config/config.yaml loaded successfully]
[2025-07-02 08:27:58,679: INFO : common : YML file: params.yaml loaded successfully]
[2025-07-02 08:27:58,683: INFO : common : YML file: schema.yaml loaded successfully]
[2025-07-02 08:27:58,684: INFO : common : Created directory at: artifacts]
[2025-07-02 08:27:58,685: INFO : common : Created directory at: artifacts/data_ingestion]
[2025-07-02 08:27:58,685: INFO : data_ingestion : file already exists: 23 KB]
[2025-07-02 08:27:58,690: INFO : main : >>>> stage Data Ingestion stage completed >>>>>]
[2025-07-02 08:27:58,690: INFO : main : >> stage Data Validation stage has started >>>>]
[2025-07-02 08:27:58,695: INFO : common : YML file: config/config.yaml loaded successfully]
[2025-07-02 08:27:58,696: INFO : common : YML file: params.yaml loaded successfully]
[2025-07-02 08:27:58,699: INFO : common : YML file: schema.yaml loaded successfully]
[2025-07-02 08:27:58,699: INFO : common : Created directory at: artifacts]
[2025-07-02 08:27:58,699: INFO : common : Created directory at: artifacts/data_validation]
[2025-07-02 08:27:58,714: INFO : main : >>>> stage Data Validation stage completed >>>>>]
[2025-07-02 08:27:58,715: INFO : main : >> stage Data Transformation stage has started >>>>]
[2025-07-02 08:27:58,718: INFO : common : YML file: config/config.yaml loaded successfully]
[2025-07-02 08:27:58,719: INFO : common : YML file: params.yaml loaded successfully]
[2025-07-02 08:27:58,721: INFO : common : YML file: schema.yaml loaded successfully]
[2025-07-02 08:27:58,721: INFO : common : Created directory at: artifacts]
[2025-07-02 08:27:58,722: INFO : common : Created directory at: artifacts/data_transformation]
[2025-07-02 08:27:58,893: INFO : data_transformation : splitted data into training and testing sets]
[2025-07-02 08:27:58,893: INFO : data_transformation : (1199, 12)]
[2025-07-02 08:27:58,894: INFO : data_transformation : (400, 12)]
[2025-07-02 08:27:58,894: INFO : main : >>>> stage Data Transformation stage completed >>>>>]
[2025-07-02 10:09:19,093: INFO : utils : NumExpr defaulting to 2 threads.]
[2025-07-02 10:09:30,958: INFO : common : Created directory at: artifacts]
[2025-07-02 10:09:34,705: INFO : main : >> stage Data Ingestion stage has started >>>>]
[2025-07-02 10:09:34,952: INFO : common : YML file: config/config.yaml loaded successfully]
[2025-07-02 10:09:34,979: INFO : common : YML file: params.yaml loaded successfully]
[2025-07-02 10:09:35,055: INFO : common : YML file: schema.yaml loaded successfully]
[2025-07-02 10:09:35,055: INFO : common : Created directory at: artifacts]
[2025-07-02 10:09:35,056: INFO : common : Created directory at: artifacts/data_ingestion]
[2025-07-02 10:09:35,056: INFO : data_ingestion : file already exists: 23 KB]
[2025-07-02 10:09:35,089: INFO : main : >>>> stage Data Ingestion stage completed >>>>>]
[2025-07-02 10:09:35,089: INFO : main : >> stage Data Validation stage has started >>>>]
[2025-07-02 10:09:35,093: INFO : common : YML file: config/config.yaml loaded successfully]
[2025-07-02 10:09:35,094: INFO : common : YML file: params.yaml loaded successfully]
[2025-07-02 10:09:35,098: INFO : common : YML file: schema.yaml loaded successfully]
[2025-07-02 10:09:35,098: INFO : common : Created directory at: artifacts]
[2025-07-02 10:09:35,178: INFO : common : Created directory at: artifacts/data_validation]
[2025-07-02 10:09:35,293: INFO : main : >>>> stage Data Validation stage completed >>>>>]
[2025-07-02 10:09:35,293: INFO : main : >> stage Data Transformation stage has started >>>>]
[2025-07-02 10:09:35,297: INFO : common : YML file: config/config.yaml loaded successfully]
[2025-07-02 10:09:35,300: INFO : common : YML file: params.yaml loaded successfully]
[2025-07-02 10:09:35,307: INFO : common : YML file: schema.yaml loaded successfully]
[2025-07-02 10:09:35,315: INFO : common : Created directory at: artifacts]
[2025-07-02 10:09:35,317: INFO : common : Created directory at: artifacts/data_transformation]
[2025-07-02 10:09:35,610: INFO : data_transformation : splitted data into training and testing sets]
[2025-07-02 10:09:35,610: INFO : data_transformation : (1199, 12)]
[2025-07-02 10:09:35,611: INFO : data_transformation : (400, 12)]
[2025-07-02 10:09:35,611: INFO : main : >>>> stage Data Transformation stage completed >>>>>]
[2025-07-03 13:31:13,451: INFO : utils : NumExpr defaulting to 2 threads.]
[2025-07-03 13:31:17,545: INFO : common : Created directory at: artifacts]
[2025-07-03 13:32:50,870: INFO : utils : NumExpr defaulting to 2 threads.]
[2025-07-03 13:32:51,110: INFO : common : Created directory at: artifacts]
[2025-07-03 13:32:52,529: INFO : main : >> stage Data Ingestion stage has started >>>>]
[2025-07-03 13:32:52,548: INFO : common : YML file: config/config.yaml loaded successfully]
[2025-07-03 13:32:52,560: INFO : common : YML file: params.yaml loaded successfully]
[2025-07-03 13:32:52,574: INFO : common : YML file: schema.yaml loaded successfully]
[2025-07-03 13:32:52,575: INFO : common : Created directory at: artifacts]
[2025-07-03 13:32:52,576: INFO : common : Created directory at: artifacts/data_ingestion]
[2025-07-03 13:32:52,577: INFO : data_ingestion : file already exists: 23 KB]
[2025-07-03 13:32:52,654: INFO : main : >>>> stage Data Ingestion stage completed >>>>>]
[2025-07-03 13:32:52,656: INFO : main : >> stage Data Validation stage has started >>>>]
[2025-07-03 13:32:52,660: INFO : common : YML file: config/config.yaml loaded successfully]
[2025-07-03 13:32:52,665: INFO : common : YML file: params.yaml loaded successfully]
[2025-07-03 13:32:52,667: INFO : common : YML file: schema.yaml loaded successfully]
[2025-07-03 13:32:52,668: INFO : common : Created directory at: artifacts]
[2025-07-03 13:32:52,668: INFO : common : Created directory at: artifacts/data_validation]
[2025-07-03 13:32:52,699: INFO : main : >>>> stage Data Validation stage completed >>>>>]
[2025-07-03 13:32:52,699: INFO : main : >> stage Data Transformation stage has started >>>>]
[2025-07-03 13:32:52,701: INFO : common : YML file: config/config.yaml loaded successfully]
[2025-07-03 13:32:52,703: INFO : common : YML file: params.yaml loaded successfully]
[2025-07-03 13:32:52,705: INFO : common : YML file: schema.yaml loaded successfully]
[2025-07-03 13:32:52,706: INFO : common : Created directory at: artifacts]
[2025-07-03 13:32:52,706: INFO : common : Created directory at: artifacts/data_transformation]
[2025-07-03 13:32:52,911: INFO : data_transformation : splitted data into training and testing sets]
[2025-07-03 13:32:52,911: INFO : data_transformation : (1199, 12)]
[2025-07-03 13:32:52,911: INFO : data_transformation : (400, 12)]
[2025-07-03 13:32:52,912: INFO : main : >>>> stage Data Transformation stage completed >>>>>]
[2025-07-03 13:32:52,912: INFO : main : >> stage  model training stage has started >>>>]
[2025-07-03 13:32:52,915: INFO : common : YML file: config/config.yaml loaded successfully]
[2025-07-03 13:32:52,917: INFO : common : YML file: params.yaml loaded successfully]
[2025-07-03 13:32:52,920: INFO : common : YML file: schema.yaml loaded successfully]
[2025-07-03 13:32:52,920: INFO : common : Created directory at: artifacts]
[2025-07-03 13:32:52,950: INFO : common : Created directory at: artifacts/model_training]
[2025-07-03 13:32:52,951: ERROR : main : name 'Path' is not defined]
Traceback (most recent call last):
  File "/home/moses/Documents/machine_learning/End_to_end_ml_project/main.py", line 31, in <module>
    obj.main()
  File "/home/moses/Documents/machine_learning/End_to_end_ml_project/src/my_project/pipeline/model_training_stage.py", line 15, in main
    training_config.train()
  File "/home/moses/Documents/machine_learning/End_to_end_ml_project/src/my_project/Components/model_training.py", line 15, in train
    print("Resolved path:", Path(self.config.train_data_path).resolve())
                            ^^^^
NameError: name 'Path' is not defined
[2025-07-03 13:33:52,811: INFO : utils : NumExpr defaulting to 2 threads.]
[2025-07-03 13:33:53,048: INFO : common : Created directory at: artifacts]
[2025-07-03 13:33:53,891: INFO : main : >> stage Data Ingestion stage has started >>>>]
[2025-07-03 13:33:53,895: INFO : common : YML file: config/config.yaml loaded successfully]
[2025-07-03 13:33:53,896: INFO : common : YML file: params.yaml loaded successfully]
[2025-07-03 13:33:53,898: INFO : common : YML file: schema.yaml loaded successfully]
[2025-07-03 13:33:53,899: INFO : common : Created directory at: artifacts]
[2025-07-03 13:33:53,899: INFO : common : Created directory at: artifacts/data_ingestion]
[2025-07-03 13:33:53,899: INFO : data_ingestion : file already exists: 23 KB]
[2025-07-03 13:33:53,902: INFO : main : >>>> stage Data Ingestion stage completed >>>>>]
[2025-07-03 13:33:53,902: INFO : main : >> stage Data Validation stage has started >>>>]
[2025-07-03 13:33:53,905: INFO : common : YML file: config/config.yaml loaded successfully]
[2025-07-03 13:33:53,906: INFO : common : YML file: params.yaml loaded successfully]
[2025-07-03 13:33:53,908: INFO : common : YML file: schema.yaml loaded successfully]
[2025-07-03 13:33:53,909: INFO : common : Created directory at: artifacts]
[2025-07-03 13:33:53,909: INFO : common : Created directory at: artifacts/data_validation]
[2025-07-03 13:33:53,920: INFO : main : >>>> stage Data Validation stage completed >>>>>]
[2025-07-03 13:33:53,920: INFO : main : >> stage Data Transformation stage has started >>>>]
[2025-07-03 13:33:53,924: INFO : common : YML file: config/config.yaml loaded successfully]
[2025-07-03 13:33:53,925: INFO : common : YML file: params.yaml loaded successfully]
[2025-07-03 13:33:53,928: INFO : common : YML file: schema.yaml loaded successfully]
[2025-07-03 13:33:53,929: INFO : common : Created directory at: artifacts]
[2025-07-03 13:33:53,930: INFO : common : Created directory at: artifacts/data_transformation]
[2025-07-03 13:33:53,972: INFO : data_transformation : splitted data into training and testing sets]
[2025-07-03 13:33:53,973: INFO : data_transformation : (1199, 12)]
[2025-07-03 13:33:53,973: INFO : data_transformation : (400, 12)]
[2025-07-03 13:33:53,973: INFO : main : >>>> stage Data Transformation stage completed >>>>>]
[2025-07-03 13:33:53,973: INFO : main : >> stage  model training stage has started >>>>]
[2025-07-03 13:33:53,976: INFO : common : YML file: config/config.yaml loaded successfully]
[2025-07-03 13:33:53,977: INFO : common : YML file: params.yaml loaded successfully]
[2025-07-03 13:33:53,979: INFO : common : YML file: schema.yaml loaded successfully]
[2025-07-03 13:33:53,979: INFO : common : Created directory at: artifacts]
[2025-07-03 13:33:53,980: INFO : common : Created directory at: artifacts/model_training]
[2025-07-03 13:33:54,136: ERROR : main : name 'logger' is not defined]
Traceback (most recent call last):
  File "/home/moses/Documents/machine_learning/End_to_end_ml_project/main.py", line 31, in <module>
    obj.main()
  File "/home/moses/Documents/machine_learning/End_to_end_ml_project/src/my_project/pipeline/model_training_stage.py", line 15, in main
    training_config.train()
  File "/home/moses/Documents/machine_learning/End_to_end_ml_project/src/my_project/Components/model_training.py", line 35, in train
    logger.info(f"Model trained and saved at {self.config.root_dir / self.config.model_name}")
    ^^^^^^
NameError: name 'logger' is not defined
[2025-07-03 13:34:54,452: INFO : utils : NumExpr defaulting to 2 threads.]
[2025-07-03 13:34:54,694: INFO : common : Created directory at: artifacts]
[2025-07-03 13:34:55,525: INFO : main : >> stage Data Ingestion stage has started >>>>]
[2025-07-03 13:34:55,528: INFO : common : YML file: config/config.yaml loaded successfully]
[2025-07-03 13:34:55,530: INFO : common : YML file: params.yaml loaded successfully]
[2025-07-03 13:34:55,532: INFO : common : YML file: schema.yaml loaded successfully]
[2025-07-03 13:34:55,533: INFO : common : Created directory at: artifacts]
[2025-07-03 13:34:55,533: INFO : common : Created directory at: artifacts/data_ingestion]
[2025-07-03 13:34:55,533: INFO : data_ingestion : file already exists: 23 KB]
[2025-07-03 13:34:55,536: INFO : main : >>>> stage Data Ingestion stage completed >>>>>]
[2025-07-03 13:34:55,536: INFO : main : >> stage Data Validation stage has started >>>>]
[2025-07-03 13:34:55,539: INFO : common : YML file: config/config.yaml loaded successfully]
[2025-07-03 13:34:55,540: INFO : common : YML file: params.yaml loaded successfully]
[2025-07-03 13:34:55,542: INFO : common : YML file: schema.yaml loaded successfully]
[2025-07-03 13:34:55,543: INFO : common : Created directory at: artifacts]
[2025-07-03 13:34:55,543: INFO : common : Created directory at: artifacts/data_validation]
[2025-07-03 13:34:55,553: INFO : main : >>>> stage Data Validation stage completed >>>>>]
[2025-07-03 13:34:55,553: INFO : main : >> stage Data Transformation stage has started >>>>]
[2025-07-03 13:34:55,556: INFO : common : YML file: config/config.yaml loaded successfully]
[2025-07-03 13:34:55,557: INFO : common : YML file: params.yaml loaded successfully]
[2025-07-03 13:34:55,559: INFO : common : YML file: schema.yaml loaded successfully]
[2025-07-03 13:34:55,560: INFO : common : Created directory at: artifacts]
[2025-07-03 13:34:55,560: INFO : common : Created directory at: artifacts/data_transformation]
[2025-07-03 13:34:55,595: INFO : data_transformation : splitted data into training and testing sets]
[2025-07-03 13:34:55,595: INFO : data_transformation : (1199, 12)]
[2025-07-03 13:34:55,595: INFO : data_transformation : (400, 12)]
[2025-07-03 13:34:55,595: INFO : main : >>>> stage Data Transformation stage completed >>>>>]
[2025-07-03 13:34:55,595: INFO : main : >> stage  model training stage has started >>>>]
[2025-07-03 13:34:55,598: INFO : common : YML file: config/config.yaml loaded successfully]
[2025-07-03 13:34:55,599: INFO : common : YML file: params.yaml loaded successfully]
[2025-07-03 13:34:55,601: INFO : common : YML file: schema.yaml loaded successfully]
[2025-07-03 13:34:55,602: INFO : common : Created directory at: artifacts]
[2025-07-03 13:34:55,602: INFO : common : Created directory at: artifacts/model_training]
[2025-07-03 13:34:55,626: INFO : model_training : Model trained and saved at artifacts/model_training/model.joblib]
[2025-07-03 13:34:55,628: ERROR : main : name 's' is not defined]
Traceback (most recent call last):
  File "/home/moses/Documents/machine_learning/End_to_end_ml_project/main.py", line 31, in <module>
    obj.main()
  File "/home/moses/Documents/machine_learning/End_to_end_ml_project/src/my_project/pipeline/model_training_stage.py", line 15, in main
    training_config.train()
  File "/home/moses/Documents/machine_learning/End_to_end_ml_project/src/my_project/Components/model_training.py", line 37, in train
    s
NameError: name 's' is not defined
[2025-07-03 13:35:27,976: INFO : utils : NumExpr defaulting to 2 threads.]
[2025-07-03 13:35:28,217: INFO : common : Created directory at: artifacts]
[2025-07-03 13:35:29,052: INFO : main : >> stage Data Ingestion stage has started >>>>]
[2025-07-03 13:35:29,056: INFO : common : YML file: config/config.yaml loaded successfully]
[2025-07-03 13:35:29,057: INFO : common : YML file: params.yaml loaded successfully]
[2025-07-03 13:35:29,059: INFO : common : YML file: schema.yaml loaded successfully]
[2025-07-03 13:35:29,060: INFO : common : Created directory at: artifacts]
[2025-07-03 13:35:29,060: INFO : common : Created directory at: artifacts/data_ingestion]
[2025-07-03 13:35:29,061: INFO : data_ingestion : file already exists: 23 KB]
[2025-07-03 13:35:29,063: INFO : main : >>>> stage Data Ingestion stage completed >>>>>]
[2025-07-03 13:35:29,063: INFO : main : >> stage Data Validation stage has started >>>>]
[2025-07-03 13:35:29,066: INFO : common : YML file: config/config.yaml loaded successfully]
[2025-07-03 13:35:29,067: INFO : common : YML file: params.yaml loaded successfully]
[2025-07-03 13:35:29,070: INFO : common : YML file: schema.yaml loaded successfully]
[2025-07-03 13:35:29,070: INFO : common : Created directory at: artifacts]
[2025-07-03 13:35:29,070: INFO : common : Created directory at: artifacts/data_validation]
[2025-07-03 13:35:29,080: INFO : main : >>>> stage Data Validation stage completed >>>>>]
[2025-07-03 13:35:29,080: INFO : main : >> stage Data Transformation stage has started >>>>]
[2025-07-03 13:35:29,083: INFO : common : YML file: config/config.yaml loaded successfully]
[2025-07-03 13:35:29,084: INFO : common : YML file: params.yaml loaded successfully]
[2025-07-03 13:35:29,086: INFO : common : YML file: schema.yaml loaded successfully]
[2025-07-03 13:35:29,087: INFO : common : Created directory at: artifacts]
[2025-07-03 13:35:29,087: INFO : common : Created directory at: artifacts/data_transformation]
[2025-07-03 13:35:29,121: INFO : data_transformation : splitted data into training and testing sets]
[2025-07-03 13:35:29,122: INFO : data_transformation : (1199, 12)]
[2025-07-03 13:35:29,122: INFO : data_transformation : (400, 12)]
[2025-07-03 13:35:29,122: INFO : main : >>>> stage Data Transformation stage completed >>>>>]
[2025-07-03 13:35:29,122: INFO : main : >> stage  model training stage has started >>>>]
[2025-07-03 13:35:29,124: INFO : common : YML file: config/config.yaml loaded successfully]
[2025-07-03 13:35:29,125: INFO : common : YML file: params.yaml loaded successfully]
[2025-07-03 13:35:29,127: INFO : common : YML file: schema.yaml loaded successfully]
[2025-07-03 13:35:29,128: INFO : common : Created directory at: artifacts]
[2025-07-03 13:35:29,128: INFO : common : Created directory at: artifacts/model_training]
[2025-07-03 13:35:29,144: INFO : model_training : Model trained and saved at artifacts/model_training/model.joblib]
[2025-07-03 13:35:29,144: INFO : main : >>>> stage  model training stage completed >>>>>]
[2025-07-05 10:45:13,540: INFO : utils : NumExpr defaulting to 2 threads.]
[2025-07-05 10:45:16,714: INFO : common : Created directory at: artifacts]
[2025-07-05 11:14:51,719: INFO : utils : NumExpr defaulting to 2 threads.]
[2025-07-05 11:14:55,188: INFO : common : Created directory at: artifacts]
[2025-07-05 11:15:17,966: INFO : main : >> stage Data Ingestion stage has started >>>>]
[2025-07-05 11:15:18,000: INFO : common : YML file: config/config.yaml loaded successfully]
[2025-07-05 11:15:18,039: INFO : common : YML file: params.yaml loaded successfully]
[2025-07-05 11:15:18,052: INFO : common : YML file: schema.yaml loaded successfully]
[2025-07-05 11:15:18,053: INFO : common : Created directory at: artifacts]
[2025-07-05 11:15:18,054: INFO : common : Created directory at: artifacts/data_ingestion]
[2025-07-05 11:15:18,054: INFO : data_ingestion : file already exists: 23 KB]
[2025-07-05 11:15:18,131: INFO : main : >>>> stage Data Ingestion stage completed >>>>>]
[2025-07-05 11:15:18,131: INFO : main : >> stage Data Validation stage has started >>>>]
[2025-07-05 11:15:18,138: INFO : common : YML file: config/config.yaml loaded successfully]
[2025-07-05 11:15:18,140: INFO : common : YML file: params.yaml loaded successfully]
[2025-07-05 11:15:18,145: INFO : common : YML file: schema.yaml loaded successfully]
[2025-07-05 11:15:18,146: INFO : common : Created directory at: artifacts]
[2025-07-05 11:15:18,146: INFO : common : Created directory at: artifacts/data_validation]
[2025-07-05 11:15:18,852: INFO : main : >>>> stage Data Validation stage completed >>>>>]
[2025-07-05 11:15:18,852: INFO : main : >> stage Data Transformation stage has started >>>>]
[2025-07-05 11:15:18,859: INFO : common : YML file: config/config.yaml loaded successfully]
[2025-07-05 11:15:18,861: INFO : common : YML file: params.yaml loaded successfully]
[2025-07-05 11:15:18,866: INFO : common : YML file: schema.yaml loaded successfully]
[2025-07-05 11:15:18,866: INFO : common : Created directory at: artifacts]
[2025-07-05 11:15:18,867: INFO : common : Created directory at: artifacts/data_transformation]
[2025-07-05 11:15:19,309: INFO : data_transformation : splitted data into training and testing sets]
[2025-07-05 11:15:19,310: INFO : data_transformation : (1199, 12)]
[2025-07-05 11:15:19,310: INFO : data_transformation : (400, 12)]
[2025-07-05 11:15:19,310: INFO : main : >>>> stage Data Transformation stage completed >>>>>]
[2025-07-05 11:15:19,310: INFO : main : >> stage  model training stage has started >>>>]
[2025-07-05 11:15:19,313: INFO : common : YML file: config/config.yaml loaded successfully]
[2025-07-05 11:15:19,314: INFO : common : YML file: params.yaml loaded successfully]
[2025-07-05 11:15:19,317: INFO : common : YML file: schema.yaml loaded successfully]
[2025-07-05 11:15:19,318: INFO : common : Created directory at: artifacts]
[2025-07-05 11:15:19,318: INFO : common : Created directory at: artifacts/model_training]
[2025-07-05 11:15:19,710: INFO : model_training : Model trained and saved at artifacts/model_training/model.joblib]
[2025-07-05 11:15:19,710: INFO : main : >>>> stage  model training stage completed >>>>>]
[2025-07-05 11:15:19,710: INFO : main : >> stage  model evaluation stage has started >>>>]
[2025-07-05 11:15:19,711: ERROR : main : EvaluationConfigurationManager.__init__() missing 3 required positional arguments: 'config_filepath', 'params_filepath', and 'schema_filepath']
Traceback (most recent call last):
  File "/home/moses/Documents/machine_learning/End_to_end_ml_project/main.py", line 37, in <module>
    obj.main()
  File "/home/moses/Documents/machine_learning/End_to_end_ml_project/src/my_project/pipeline/model_evaluation_stage.py", line 14, in main
    config = EvaluationConfigurationManager()
             ^^^^^^^^^^^^^^^^^^^^^^^^^^^^^^^^
TypeError: EvaluationConfigurationManager.__init__() missing 3 required positional arguments: 'config_filepath', 'params_filepath', and 'schema_filepath'
[2025-07-05 12:29:38,038: INFO : utils : NumExpr defaulting to 2 threads.]
[2025-07-05 12:29:42,475: INFO : common : Created directory at: artifacts]
[2025-07-05 12:29:55,873: INFO : main : >> stage Data Ingestion stage has started >>>>]
[2025-07-05 12:29:55,930: INFO : common : YML file: config/config.yaml loaded successfully]
[2025-07-05 12:29:55,975: INFO : common : YML file: params.yaml loaded successfully]
[2025-07-05 12:29:56,022: INFO : common : YML file: schema.yaml loaded successfully]
[2025-07-05 12:29:56,023: INFO : common : Created directory at: artifacts]
[2025-07-05 12:29:56,024: INFO : common : Created directory at: artifacts/data_ingestion]
[2025-07-05 12:29:56,028: INFO : data_ingestion : file already exists: 23 KB]
[2025-07-05 12:29:56,070: INFO : main : >>>> stage Data Ingestion stage completed >>>>>]
[2025-07-05 12:29:56,070: INFO : main : >> stage Data Validation stage has started >>>>]
[2025-07-05 12:29:56,073: INFO : common : YML file: config/config.yaml loaded successfully]
[2025-07-05 12:29:56,075: INFO : common : YML file: params.yaml loaded successfully]
[2025-07-05 12:29:56,078: INFO : common : YML file: schema.yaml loaded successfully]
[2025-07-05 12:29:56,079: INFO : common : Created directory at: artifacts]
[2025-07-05 12:29:56,079: INFO : common : Created directory at: artifacts/data_validation]
[2025-07-05 12:29:56,120: INFO : main : >>>> stage Data Validation stage completed >>>>>]
[2025-07-05 12:29:56,120: INFO : main : >> stage Data Transformation stage has started >>>>]
[2025-07-05 12:29:56,124: INFO : common : YML file: config/config.yaml loaded successfully]
[2025-07-05 12:29:56,125: INFO : common : YML file: params.yaml loaded successfully]
[2025-07-05 12:29:56,127: INFO : common : YML file: schema.yaml loaded successfully]
[2025-07-05 12:29:56,127: INFO : common : Created directory at: artifacts]
[2025-07-05 12:29:56,127: INFO : common : Created directory at: artifacts/data_transformation]
[2025-07-05 12:29:56,276: INFO : data_transformation : splitted data into training and testing sets]
[2025-07-05 12:29:56,279: INFO : data_transformation : (1199, 12)]
[2025-07-05 12:29:56,280: INFO : data_transformation : (400, 12)]
[2025-07-05 12:29:56,280: INFO : main : >>>> stage Data Transformation stage completed >>>>>]
[2025-07-05 12:29:56,280: INFO : main : >> stage  model training stage has started >>>>]
[2025-07-05 12:29:56,289: INFO : common : YML file: config/config.yaml loaded successfully]
[2025-07-05 12:29:56,292: INFO : common : YML file: params.yaml loaded successfully]
[2025-07-05 12:29:56,296: INFO : common : YML file: schema.yaml loaded successfully]
[2025-07-05 12:29:56,296: INFO : common : Created directory at: artifacts]
[2025-07-05 12:29:56,297: INFO : common : Created directory at: artifacts/model_training]
[2025-07-05 12:29:56,416: INFO : model_training : Model trained and saved at artifacts/model_training/model.joblib]
[2025-07-05 12:29:56,419: INFO : main : >>>> stage  model training stage completed >>>>>]
[2025-07-05 12:29:56,421: INFO : main : >> stage  model evaluation stage has started >>>>]
[2025-07-05 12:29:56,421: ERROR : main : EvaluationConfigurationManager.__init__() missing 3 required positional arguments: 'config_filepath', 'params_filepath', and 'schema_filepath']
Traceback (most recent call last):
  File "/home/moses/Documents/machine_learning/End_to_end_ml_project/main.py", line 37, in <module>
    obj.main()
  File "/home/moses/Documents/machine_learning/End_to_end_ml_project/src/my_project/pipeline/model_evaluation_stage.py", line 14, in main
    config = EvaluationConfigurationManager()
             ^^^^^^^^^^^^^^^^^^^^^^^^^^^^^^^^
TypeError: EvaluationConfigurationManager.__init__() missing 3 required positional arguments: 'config_filepath', 'params_filepath', and 'schema_filepath'
[2025-07-05 12:31:26,196: INFO : utils : NumExpr defaulting to 2 threads.]
[2025-07-05 12:31:26,844: INFO : common : Created directory at: artifacts]
[2025-07-05 12:31:28,730: INFO : main : >> stage Data Ingestion stage has started >>>>]
[2025-07-05 12:31:28,736: INFO : common : YML file: config/config.yaml loaded successfully]
[2025-07-05 12:31:28,738: INFO : common : YML file: params.yaml loaded successfully]
[2025-07-05 12:31:28,741: INFO : common : YML file: schema.yaml loaded successfully]
[2025-07-05 12:31:28,742: INFO : common : Created directory at: artifacts]
[2025-07-05 12:31:28,743: INFO : common : Created directory at: artifacts/data_ingestion]
[2025-07-05 12:31:28,743: INFO : data_ingestion : file already exists: 23 KB]
[2025-07-05 12:31:28,747: INFO : main : >>>> stage Data Ingestion stage completed >>>>>]
[2025-07-05 12:31:28,747: INFO : main : >> stage Data Validation stage has started >>>>]
[2025-07-05 12:31:28,750: INFO : common : YML file: config/config.yaml loaded successfully]
[2025-07-05 12:31:28,752: INFO : common : YML file: params.yaml loaded successfully]
[2025-07-05 12:31:28,754: INFO : common : YML file: schema.yaml loaded successfully]
[2025-07-05 12:31:28,755: INFO : common : Created directory at: artifacts]
[2025-07-05 12:31:28,756: INFO : common : Created directory at: artifacts/data_validation]
[2025-07-05 12:31:28,768: INFO : main : >>>> stage Data Validation stage completed >>>>>]
[2025-07-05 12:31:28,769: INFO : main : >> stage Data Transformation stage has started >>>>]
[2025-07-05 12:31:28,773: INFO : common : YML file: config/config.yaml loaded successfully]
[2025-07-05 12:31:28,774: INFO : common : YML file: params.yaml loaded successfully]
[2025-07-05 12:31:28,777: INFO : common : YML file: schema.yaml loaded successfully]
[2025-07-05 12:31:28,777: INFO : common : Created directory at: artifacts]
[2025-07-05 12:31:28,777: INFO : common : Created directory at: artifacts/data_transformation]
[2025-07-05 12:31:28,814: INFO : data_transformation : splitted data into training and testing sets]
[2025-07-05 12:31:28,815: INFO : data_transformation : (1199, 12)]
[2025-07-05 12:31:28,815: INFO : data_transformation : (400, 12)]
[2025-07-05 12:31:28,815: INFO : main : >>>> stage Data Transformation stage completed >>>>>]
[2025-07-05 12:31:28,815: INFO : main : >> stage  model training stage has started >>>>]
[2025-07-05 12:31:28,818: INFO : common : YML file: config/config.yaml loaded successfully]
[2025-07-05 12:31:28,819: INFO : common : YML file: params.yaml loaded successfully]
[2025-07-05 12:31:28,821: INFO : common : YML file: schema.yaml loaded successfully]
[2025-07-05 12:31:28,822: INFO : common : Created directory at: artifacts]
[2025-07-05 12:31:28,823: INFO : common : Created directory at: artifacts/model_training]
[2025-07-05 12:31:28,843: INFO : model_training : Model trained and saved at artifacts/model_training/model.joblib]
[2025-07-05 12:31:28,843: INFO : main : >>>> stage  model training stage completed >>>>>]
[2025-07-05 12:31:28,844: INFO : main : >> stage  model evaluation stage has started >>>>]
[2025-07-05 12:31:28,844: ERROR : main : EvaluationConfigurationManager.__init__() missing 3 required positional arguments: 'config_filepath', 'params_filepath', and 'schema_filepath']
Traceback (most recent call last):
  File "/home/moses/Documents/machine_learning/End_to_end_ml_project/main.py", line 37, in <module>
    obj.main()
  File "/home/moses/Documents/machine_learning/End_to_end_ml_project/src/my_project/pipeline/model_evaluation_stage.py", line 14, in main
    config = EvaluationConfigurationManager()
             ^^^^^^^^^^^^^^^^^^^^^^^^^^^^^^^^
TypeError: EvaluationConfigurationManager.__init__() missing 3 required positional arguments: 'config_filepath', 'params_filepath', and 'schema_filepath'
[2025-07-05 12:32:38,314: INFO : utils : NumExpr defaulting to 2 threads.]
[2025-07-05 12:32:38,583: INFO : common : Created directory at: artifacts]
[2025-07-05 12:32:39,484: INFO : main : >> stage Data Ingestion stage has started >>>>]
[2025-07-05 12:32:39,488: INFO : common : YML file: config/config.yaml loaded successfully]
[2025-07-05 12:32:39,489: INFO : common : YML file: params.yaml loaded successfully]
[2025-07-05 12:32:39,492: INFO : common : YML file: schema.yaml loaded successfully]
[2025-07-05 12:32:39,492: INFO : common : Created directory at: artifacts]
[2025-07-05 12:32:39,492: INFO : common : Created directory at: artifacts/data_ingestion]
[2025-07-05 12:32:39,493: INFO : data_ingestion : file already exists: 23 KB]
[2025-07-05 12:32:39,495: INFO : main : >>>> stage Data Ingestion stage completed >>>>>]
[2025-07-05 12:32:39,495: INFO : main : >> stage Data Validation stage has started >>>>]
[2025-07-05 12:32:39,499: INFO : common : YML file: config/config.yaml loaded successfully]
[2025-07-05 12:32:39,500: INFO : common : YML file: params.yaml loaded successfully]
[2025-07-05 12:32:39,502: INFO : common : YML file: schema.yaml loaded successfully]
[2025-07-05 12:32:39,503: INFO : common : Created directory at: artifacts]
[2025-07-05 12:32:39,503: INFO : common : Created directory at: artifacts/data_validation]
[2025-07-05 12:32:39,514: INFO : main : >>>> stage Data Validation stage completed >>>>>]
[2025-07-05 12:32:39,515: INFO : main : >> stage Data Transformation stage has started >>>>]
[2025-07-05 12:32:39,519: INFO : common : YML file: config/config.yaml loaded successfully]
[2025-07-05 12:32:39,520: INFO : common : YML file: params.yaml loaded successfully]
[2025-07-05 12:32:39,523: INFO : common : YML file: schema.yaml loaded successfully]
[2025-07-05 12:32:39,523: INFO : common : Created directory at: artifacts]
[2025-07-05 12:32:39,523: INFO : common : Created directory at: artifacts/data_transformation]
[2025-07-05 12:32:39,560: INFO : data_transformation : splitted data into training and testing sets]
[2025-07-05 12:32:39,560: INFO : data_transformation : (1199, 12)]
[2025-07-05 12:32:39,560: INFO : data_transformation : (400, 12)]
[2025-07-05 12:32:39,561: INFO : main : >>>> stage Data Transformation stage completed >>>>>]
[2025-07-05 12:32:39,561: INFO : main : >> stage  model training stage has started >>>>]
[2025-07-05 12:32:39,566: INFO : common : YML file: config/config.yaml loaded successfully]
[2025-07-05 12:32:39,567: INFO : common : YML file: params.yaml loaded successfully]
[2025-07-05 12:32:39,570: INFO : common : YML file: schema.yaml loaded successfully]
[2025-07-05 12:32:39,570: INFO : common : Created directory at: artifacts]
[2025-07-05 12:32:39,571: INFO : common : Created directory at: artifacts/model_training]
[2025-07-05 12:32:39,586: INFO : model_training : Model trained and saved at artifacts/model_training/model.joblib]
[2025-07-05 12:32:39,588: INFO : main : >>>> stage  model training stage completed >>>>>]
[2025-07-05 12:32:39,588: INFO : main : >> stage  model evaluation stage has started >>>>]
[2025-07-05 12:32:39,592: INFO : common : YML file: config/config.yaml loaded successfully]
[2025-07-05 12:32:39,596: INFO : common : YML file: params.yaml loaded successfully]
[2025-07-05 12:32:39,603: INFO : common : YML file: schema.yaml loaded successfully]
[2025-07-05 12:32:39,604: INFO : common : Created directory at: artifacts]
[2025-07-05 12:32:39,605: ERROR : main : "'ConfigBox' object has no attribute 'root_dir'"]
Traceback (most recent call last):
  File "/home/moses/anaconda3/lib/python3.11/site-packages/box/box.py", line 503, in __getitem__
    return super().__getitem__(item)
           ^^^^^^^^^^^^^^^^^^^^^^^^^
KeyError: 'root_dir'

The above exception was the direct cause of the following exception:

Traceback (most recent call last):
  File "/home/moses/anaconda3/lib/python3.11/site-packages/box/box.py", line 536, in __getattr__
    value = self.__getitem__(item, _ignore_default=True)
            ^^^^^^^^^^^^^^^^^^^^^^^^^^^^^^^^^^^^^^^^^^^^
  File "/home/moses/anaconda3/lib/python3.11/site-packages/box/box.py", line 524, in __getitem__
    raise BoxKeyError(str(err)) from _exception_cause(err)
box.exceptions.BoxKeyError: "'root_dir'"

During handling of the above exception, another exception occurred:

Traceback (most recent call last):
  File "/home/moses/anaconda3/lib/python3.11/site-packages/box/box.py", line 538, in __getattr__
    value = object.__getattribute__(self, item)
            ^^^^^^^^^^^^^^^^^^^^^^^^^^^^^^^^^^^
AttributeError: 'ConfigBox' object has no attribute 'root_dir'

The above exception was the direct cause of the following exception:

Traceback (most recent call last):
  File "/home/moses/anaconda3/lib/python3.11/site-packages/box/config_box.py", line 28, in __getattr__
    return super().__getattr__(item)
           ^^^^^^^^^^^^^^^^^^^^^^^^^
  File "/home/moses/anaconda3/lib/python3.11/site-packages/box/box.py", line 552, in __getattr__
    raise BoxKeyError(str(err)) from _exception_cause(err)
box.exceptions.BoxKeyError: "'ConfigBox' object has no attribute 'root_dir'"

During handling of the above exception, another exception occurred:

Traceback (most recent call last):
  File "/home/moses/anaconda3/lib/python3.11/site-packages/box/box.py", line 503, in __getitem__
    return super().__getitem__(item)
           ^^^^^^^^^^^^^^^^^^^^^^^^^
KeyError: 'root_dir'

The above exception was the direct cause of the following exception:

Traceback (most recent call last):
  File "/home/moses/anaconda3/lib/python3.11/site-packages/box/box.py", line 536, in __getattr__
    value = self.__getitem__(item, _ignore_default=True)
            ^^^^^^^^^^^^^^^^^^^^^^^^^^^^^^^^^^^^^^^^^^^^
  File "/home/moses/anaconda3/lib/python3.11/site-packages/box/box.py", line 524, in __getitem__
    raise BoxKeyError(str(err)) from _exception_cause(err)
box.exceptions.BoxKeyError: "'root_dir'"

During handling of the above exception, another exception occurred:

Traceback (most recent call last):
  File "/home/moses/anaconda3/lib/python3.11/site-packages/box/box.py", line 538, in __getattr__
    value = object.__getattribute__(self, item)
            ^^^^^^^^^^^^^^^^^^^^^^^^^^^^^^^^^^^
AttributeError: 'ConfigBox' object has no attribute 'root_dir'

The above exception was the direct cause of the following exception:

Traceback (most recent call last):
  File "/home/moses/Documents/machine_learning/End_to_end_ml_project/main.py", line 37, in <module>
    obj.main()
  File "/home/moses/Documents/machine_learning/End_to_end_ml_project/src/my_project/pipeline/model_evaluation_stage.py", line 15, in main
    model_evaluation_config = config.get_evaluation_config()
                              ^^^^^^^^^^^^^^^^^^^^^^^^^^^^^^
  File "/home/moses/Documents/machine_learning/End_to_end_ml_project/src/my_project/config/configuration.py", line 153, in get_evaluation_config
    create_directories([self.config.root_dir])
                        ^^^^^^^^^^^^^^^^^^^^
  File "/home/moses/anaconda3/lib/python3.11/site-packages/box/config_box.py", line 30, in __getattr__
    return super().__getattr__(item.lower())
           ^^^^^^^^^^^^^^^^^^^^^^^^^^^^^^^^^
  File "/home/moses/anaconda3/lib/python3.11/site-packages/box/box.py", line 552, in __getattr__
    raise BoxKeyError(str(err)) from _exception_cause(err)
box.exceptions.BoxKeyError: "'ConfigBox' object has no attribute 'root_dir'"
[2025-07-05 12:40:10,872: INFO : utils : NumExpr defaulting to 2 threads.]
[2025-07-05 12:40:11,148: INFO : common : Created directory at: artifacts]
[2025-07-05 12:40:12,034: INFO : main : >> stage Data Ingestion stage has started >>>>]
[2025-07-05 12:40:12,038: INFO : common : YML file: config/config.yaml loaded successfully]
[2025-07-05 12:40:12,040: INFO : common : YML file: params.yaml loaded successfully]
[2025-07-05 12:40:12,043: INFO : common : YML file: schema.yaml loaded successfully]
[2025-07-05 12:40:12,044: INFO : common : Created directory at: artifacts]
[2025-07-05 12:40:12,044: INFO : common : Created directory at: artifacts/data_ingestion]
[2025-07-05 12:40:12,044: INFO : data_ingestion : file already exists: 23 KB]
[2025-07-05 12:40:12,047: INFO : main : >>>> stage Data Ingestion stage completed >>>>>]
[2025-07-05 12:40:12,047: INFO : main : >> stage Data Validation stage has started >>>>]
[2025-07-05 12:40:12,050: INFO : common : YML file: config/config.yaml loaded successfully]
[2025-07-05 12:40:12,051: INFO : common : YML file: params.yaml loaded successfully]
[2025-07-05 12:40:12,054: INFO : common : YML file: schema.yaml loaded successfully]
[2025-07-05 12:40:12,054: INFO : common : Created directory at: artifacts]
[2025-07-05 12:40:12,054: INFO : common : Created directory at: artifacts/data_validation]
[2025-07-05 12:40:12,084: INFO : main : >>>> stage Data Validation stage completed >>>>>]
[2025-07-05 12:40:12,084: INFO : main : >> stage Data Transformation stage has started >>>>]
[2025-07-05 12:40:12,088: INFO : common : YML file: config/config.yaml loaded successfully]
[2025-07-05 12:40:12,089: INFO : common : YML file: params.yaml loaded successfully]
[2025-07-05 12:40:12,093: INFO : common : YML file: schema.yaml loaded successfully]
[2025-07-05 12:40:12,093: INFO : common : Created directory at: artifacts]
[2025-07-05 12:40:12,093: INFO : common : Created directory at: artifacts/data_transformation]
[2025-07-05 12:40:12,130: INFO : data_transformation : splitted data into training and testing sets]
[2025-07-05 12:40:12,130: INFO : data_transformation : (1199, 12)]
[2025-07-05 12:40:12,130: INFO : data_transformation : (400, 12)]
[2025-07-05 12:40:12,130: INFO : main : >>>> stage Data Transformation stage completed >>>>>]
[2025-07-05 12:40:12,130: INFO : main : >> stage  model training stage has started >>>>]
[2025-07-05 12:40:12,134: INFO : common : YML file: config/config.yaml loaded successfully]
[2025-07-05 12:40:12,135: INFO : common : YML file: params.yaml loaded successfully]
[2025-07-05 12:40:12,137: INFO : common : YML file: schema.yaml loaded successfully]
[2025-07-05 12:40:12,137: INFO : common : Created directory at: artifacts]
[2025-07-05 12:40:12,138: INFO : common : Created directory at: artifacts/model_training]
[2025-07-05 12:40:12,157: INFO : model_training : Model trained and saved at artifacts/model_training/model.joblib]
[2025-07-05 12:40:12,158: INFO : main : >>>> stage  model training stage completed >>>>>]
[2025-07-05 12:40:12,158: INFO : main : >> stage  model evaluation stage has started >>>>]
[2025-07-05 12:40:12,161: INFO : common : YML file: config/config.yaml loaded successfully]
[2025-07-05 12:40:12,162: INFO : common : YML file: params.yaml loaded successfully]
[2025-07-05 12:40:12,164: INFO : common : YML file: schema.yaml loaded successfully]
[2025-07-05 12:40:12,164: INFO : common : Created directory at: artifacts]
[2025-07-05 12:40:12,205: INFO : common : Created directory at: artifacts/model_evaluation]
[2025-07-05 12:40:12,206: ERROR : main : "'ConfigBox' object has no attribute 'metric_file_name'"]
Traceback (most recent call last):
  File "/home/moses/anaconda3/lib/python3.11/site-packages/box/box.py", line 503, in __getitem__
    return super().__getitem__(item)
           ^^^^^^^^^^^^^^^^^^^^^^^^^
KeyError: 'metric_file_name'

The above exception was the direct cause of the following exception:

Traceback (most recent call last):
  File "/home/moses/anaconda3/lib/python3.11/site-packages/box/box.py", line 536, in __getattr__
    value = self.__getitem__(item, _ignore_default=True)
            ^^^^^^^^^^^^^^^^^^^^^^^^^^^^^^^^^^^^^^^^^^^^
  File "/home/moses/anaconda3/lib/python3.11/site-packages/box/box.py", line 524, in __getitem__
    raise BoxKeyError(str(err)) from _exception_cause(err)
box.exceptions.BoxKeyError: "'metric_file_name'"

During handling of the above exception, another exception occurred:

Traceback (most recent call last):
  File "/home/moses/anaconda3/lib/python3.11/site-packages/box/box.py", line 538, in __getattr__
    value = object.__getattribute__(self, item)
            ^^^^^^^^^^^^^^^^^^^^^^^^^^^^^^^^^^^
AttributeError: 'ConfigBox' object has no attribute 'metric_file_name'

The above exception was the direct cause of the following exception:

Traceback (most recent call last):
  File "/home/moses/anaconda3/lib/python3.11/site-packages/box/config_box.py", line 28, in __getattr__
    return super().__getattr__(item)
           ^^^^^^^^^^^^^^^^^^^^^^^^^
  File "/home/moses/anaconda3/lib/python3.11/site-packages/box/box.py", line 552, in __getattr__
    raise BoxKeyError(str(err)) from _exception_cause(err)
box.exceptions.BoxKeyError: "'ConfigBox' object has no attribute 'metric_file_name'"

During handling of the above exception, another exception occurred:

Traceback (most recent call last):
  File "/home/moses/anaconda3/lib/python3.11/site-packages/box/box.py", line 503, in __getitem__
    return super().__getitem__(item)
           ^^^^^^^^^^^^^^^^^^^^^^^^^
KeyError: 'metric_file_name'

The above exception was the direct cause of the following exception:

Traceback (most recent call last):
  File "/home/moses/anaconda3/lib/python3.11/site-packages/box/box.py", line 536, in __getattr__
    value = self.__getitem__(item, _ignore_default=True)
            ^^^^^^^^^^^^^^^^^^^^^^^^^^^^^^^^^^^^^^^^^^^^
  File "/home/moses/anaconda3/lib/python3.11/site-packages/box/box.py", line 524, in __getitem__
    raise BoxKeyError(str(err)) from _exception_cause(err)
box.exceptions.BoxKeyError: "'metric_file_name'"

During handling of the above exception, another exception occurred:

Traceback (most recent call last):
  File "/home/moses/anaconda3/lib/python3.11/site-packages/box/box.py", line 538, in __getattr__
    value = object.__getattribute__(self, item)
            ^^^^^^^^^^^^^^^^^^^^^^^^^^^^^^^^^^^
AttributeError: 'ConfigBox' object has no attribute 'metric_file_name'

The above exception was the direct cause of the following exception:

Traceback (most recent call last):
  File "/home/moses/Documents/machine_learning/End_to_end_ml_project/main.py", line 37, in <module>
    obj.main()
  File "/home/moses/Documents/machine_learning/End_to_end_ml_project/src/my_project/pipeline/model_evaluation_stage.py", line 15, in main
    model_evaluation_config = config.get_evaluation_config()
                              ^^^^^^^^^^^^^^^^^^^^^^^^^^^^^^
  File "/home/moses/Documents/machine_learning/End_to_end_ml_project/src/my_project/config/configuration.py", line 161, in get_evaluation_config
    metric_file_name= config.metric_file_name,
                      ^^^^^^^^^^^^^^^^^^^^^^^
  File "/home/moses/anaconda3/lib/python3.11/site-packages/box/config_box.py", line 30, in __getattr__
    return super().__getattr__(item.lower())
           ^^^^^^^^^^^^^^^^^^^^^^^^^^^^^^^^^
  File "/home/moses/anaconda3/lib/python3.11/site-packages/box/box.py", line 552, in __getattr__
    raise BoxKeyError(str(err)) from _exception_cause(err)
box.exceptions.BoxKeyError: "'ConfigBox' object has no attribute 'metric_file_name'"
[2025-07-05 12:44:22,384: INFO : utils : NumExpr defaulting to 2 threads.]
[2025-07-05 12:44:22,627: INFO : common : Created directory at: artifacts]
[2025-07-05 12:44:23,464: INFO : main : >> stage Data Ingestion stage has started >>>>]
[2025-07-05 12:44:23,469: INFO : common : YML file: config/config.yaml loaded successfully]
[2025-07-05 12:44:23,470: INFO : common : YML file: params.yaml loaded successfully]
[2025-07-05 12:44:23,472: INFO : common : YML file: schema.yaml loaded successfully]
[2025-07-05 12:44:23,473: INFO : common : Created directory at: artifacts]
[2025-07-05 12:44:23,473: INFO : common : Created directory at: artifacts/data_ingestion]
[2025-07-05 12:44:23,473: INFO : data_ingestion : file already exists: 23 KB]
[2025-07-05 12:44:23,476: INFO : main : >>>> stage Data Ingestion stage completed >>>>>]
[2025-07-05 12:44:23,476: INFO : main : >> stage Data Validation stage has started >>>>]
[2025-07-05 12:44:23,479: INFO : common : YML file: config/config.yaml loaded successfully]
[2025-07-05 12:44:23,480: INFO : common : YML file: params.yaml loaded successfully]
[2025-07-05 12:44:23,483: INFO : common : YML file: schema.yaml loaded successfully]
[2025-07-05 12:44:23,483: INFO : common : Created directory at: artifacts]
[2025-07-05 12:44:23,483: INFO : common : Created directory at: artifacts/data_validation]
[2025-07-05 12:44:23,494: INFO : main : >>>> stage Data Validation stage completed >>>>>]
[2025-07-05 12:44:23,494: INFO : main : >> stage Data Transformation stage has started >>>>]
[2025-07-05 12:44:23,498: INFO : common : YML file: config/config.yaml loaded successfully]
[2025-07-05 12:44:23,499: INFO : common : YML file: params.yaml loaded successfully]
[2025-07-05 12:44:23,501: INFO : common : YML file: schema.yaml loaded successfully]
[2025-07-05 12:44:23,501: INFO : common : Created directory at: artifacts]
[2025-07-05 12:44:23,501: INFO : common : Created directory at: artifacts/data_transformation]
[2025-07-05 12:44:23,536: INFO : data_transformation : splitted data into training and testing sets]
[2025-07-05 12:44:23,536: INFO : data_transformation : (1199, 12)]
[2025-07-05 12:44:23,536: INFO : data_transformation : (400, 12)]
[2025-07-05 12:44:23,536: INFO : main : >>>> stage Data Transformation stage completed >>>>>]
[2025-07-05 12:44:23,536: INFO : main : >> stage  model training stage has started >>>>]
[2025-07-05 12:44:23,539: INFO : common : YML file: config/config.yaml loaded successfully]
[2025-07-05 12:44:23,541: INFO : common : YML file: params.yaml loaded successfully]
[2025-07-05 12:44:23,543: INFO : common : YML file: schema.yaml loaded successfully]
[2025-07-05 12:44:23,544: INFO : common : Created directory at: artifacts]
[2025-07-05 12:44:23,544: INFO : common : Created directory at: artifacts/model_training]
[2025-07-05 12:44:23,559: INFO : model_training : Model trained and saved at artifacts/model_training/model.joblib]
[2025-07-05 12:44:23,560: INFO : main : >>>> stage  model training stage completed >>>>>]
[2025-07-05 12:44:23,560: INFO : main : >> stage  model evaluation stage has started >>>>]
[2025-07-05 12:44:23,563: INFO : common : YML file: config/config.yaml loaded successfully]
[2025-07-05 12:44:23,564: INFO : common : YML file: params.yaml loaded successfully]
[2025-07-05 12:44:23,566: INFO : common : YML file: schema.yaml loaded successfully]
[2025-07-05 12:44:23,567: INFO : common : Created directory at: artifacts]
[2025-07-05 12:44:23,567: INFO : common : Created directory at: artifacts/model_evaluation]
[2025-07-05 12:44:23,624: ERROR : main : name 'mean_absolute_error' is not defined]
Traceback (most recent call last):
  File "/home/moses/Documents/machine_learning/End_to_end_ml_project/main.py", line 37, in <module>
    obj.main()
  File "/home/moses/Documents/machine_learning/End_to_end_ml_project/src/my_project/pipeline/model_evaluation_stage.py", line 17, in main
    model_evaluation_config.save_results()
  File "/home/moses/Documents/machine_learning/End_to_end_ml_project/src/my_project/Components/model_evaluation.py", line 32, in save_results
    rmse, mae, r2 = self.eval_metrics(y_test, predicted_values)
                    ^^^^^^^^^^^^^^^^^^^^^^^^^^^^^^^^^^^^^^^^^^^
  File "/home/moses/Documents/machine_learning/End_to_end_ml_project/src/my_project/Components/model_evaluation.py", line 18, in eval_metrics
    mae = mean_absolute_error(actual, predicted)
          ^^^^^^^^^^^^^^^^^^^
NameError: name 'mean_absolute_error' is not defined
[2025-07-05 12:45:34,613: INFO : utils : NumExpr defaulting to 2 threads.]
[2025-07-05 12:45:34,862: INFO : common : Created directory at: artifacts]
[2025-07-05 12:45:35,717: INFO : main : >> stage Data Ingestion stage has started >>>>]
[2025-07-05 12:45:35,721: INFO : common : YML file: config/config.yaml loaded successfully]
[2025-07-05 12:45:35,722: INFO : common : YML file: params.yaml loaded successfully]
[2025-07-05 12:45:35,726: INFO : common : YML file: schema.yaml loaded successfully]
[2025-07-05 12:45:35,726: INFO : common : Created directory at: artifacts]
[2025-07-05 12:45:35,727: INFO : common : Created directory at: artifacts/data_ingestion]
[2025-07-05 12:45:35,727: INFO : data_ingestion : file already exists: 23 KB]
[2025-07-05 12:45:35,729: INFO : main : >>>> stage Data Ingestion stage completed >>>>>]
[2025-07-05 12:45:35,729: INFO : main : >> stage Data Validation stage has started >>>>]
[2025-07-05 12:45:35,734: INFO : common : YML file: config/config.yaml loaded successfully]
[2025-07-05 12:45:35,736: INFO : common : YML file: params.yaml loaded successfully]
[2025-07-05 12:45:35,738: INFO : common : YML file: schema.yaml loaded successfully]
[2025-07-05 12:45:35,738: INFO : common : Created directory at: artifacts]
[2025-07-05 12:45:35,738: INFO : common : Created directory at: artifacts/data_validation]
[2025-07-05 12:45:35,749: INFO : main : >>>> stage Data Validation stage completed >>>>>]
[2025-07-05 12:45:35,749: INFO : main : >> stage Data Transformation stage has started >>>>]
[2025-07-05 12:45:35,753: INFO : common : YML file: config/config.yaml loaded successfully]
[2025-07-05 12:45:35,754: INFO : common : YML file: params.yaml loaded successfully]
[2025-07-05 12:45:35,756: INFO : common : YML file: schema.yaml loaded successfully]
[2025-07-05 12:45:35,756: INFO : common : Created directory at: artifacts]
[2025-07-05 12:45:35,757: INFO : common : Created directory at: artifacts/data_transformation]
[2025-07-05 12:45:35,792: INFO : data_transformation : splitted data into training and testing sets]
[2025-07-05 12:45:35,792: INFO : data_transformation : (1199, 12)]
[2025-07-05 12:45:35,792: INFO : data_transformation : (400, 12)]
[2025-07-05 12:45:35,792: INFO : main : >>>> stage Data Transformation stage completed >>>>>]
[2025-07-05 12:45:35,792: INFO : main : >> stage  model training stage has started >>>>]
[2025-07-05 12:45:35,795: INFO : common : YML file: config/config.yaml loaded successfully]
[2025-07-05 12:45:35,796: INFO : common : YML file: params.yaml loaded successfully]
[2025-07-05 12:45:35,798: INFO : common : YML file: schema.yaml loaded successfully]
[2025-07-05 12:45:35,799: INFO : common : Created directory at: artifacts]
[2025-07-05 12:45:35,799: INFO : common : Created directory at: artifacts/model_training]
[2025-07-05 12:45:35,814: INFO : model_training : Model trained and saved at artifacts/model_training/model.joblib]
[2025-07-05 12:45:35,815: INFO : main : >>>> stage  model training stage completed >>>>>]
[2025-07-05 12:45:35,815: INFO : main : >> stage  model evaluation stage has started >>>>]
[2025-07-05 12:45:35,818: INFO : common : YML file: config/config.yaml loaded successfully]
[2025-07-05 12:45:35,819: INFO : common : YML file: params.yaml loaded successfully]
[2025-07-05 12:45:35,821: INFO : common : YML file: schema.yaml loaded successfully]
[2025-07-05 12:45:35,821: INFO : common : Created directory at: artifacts]
[2025-07-05 12:45:35,821: INFO : common : Created directory at: artifacts/model_evaluation]
[2025-07-05 12:45:35,831: INFO : common : json file saved at: artifacts/model_evaluation/metrics.json]
[2025-07-05 12:45:35,831: INFO : main : >>>> stage  model evaluation stage completed >>>>>]
[2025-07-07 21:13:20,731: INFO : _internal : [31m[1mWARNING: This is a development server. Do not use it in a production deployment. Use a production WSGI server instead.[0m
 * Running on http://127.0.0.1:5000]
[2025-07-07 21:13:20,770: INFO : _internal : [33mPress CTRL+C to quit[0m]
[2025-07-07 21:13:20,920: INFO : _internal :  * Restarting with watchdog (inotify)]
[2025-07-07 21:13:21,818: WARNING : _internal :  * Debugger is active!]
[2025-07-07 21:13:21,924: INFO : _internal :  * Debugger PIN: 717-999-919]
[2025-07-07 21:14:10,118: INFO : _internal : 127.0.0.1 - - [07/Jul/2025 21:14:10] "GET / HTTP/1.1" 200 -]
[2025-07-07 21:14:12,136: INFO : _internal : 127.0.0.1 - - [07/Jul/2025 21:14:12] "[33mGET /favicon.ico HTTP/1.1[0m" 404 -]
[2025-07-08 10:28:24,840: INFO : _internal : [31m[1mWARNING: This is a development server. Do not use it in a production deployment. Use a production WSGI server instead.[0m
 * Running on http://127.0.0.1:5000]
[2025-07-08 10:28:24,865: INFO : _internal : [33mPress CTRL+C to quit[0m]
[2025-07-08 10:28:24,936: INFO : _internal :  * Restarting with watchdog (inotify)]
[2025-07-08 10:28:25,795: WARNING : _internal :  * Debugger is active!]
[2025-07-08 10:28:25,795: INFO : _internal :  * Debugger PIN: 788-798-566]
[2025-07-08 10:29:54,681: INFO : _internal : 127.0.0.1 - - [08/Jul/2025 10:29:54] "[33mGET /favicon.ico HTTP/1.1[0m" 404 -]
[2025-07-08 10:29:57,143: INFO : _internal : 127.0.0.1 - - [08/Jul/2025 10:29:57] "GET / HTTP/1.1" 200 -]
[2025-07-08 10:29:58,627: INFO : _internal : 127.0.0.1 - - [08/Jul/2025 10:29:58] "GET / HTTP/1.1" 200 -]
[2025-07-08 10:29:59,554: INFO : _internal : 127.0.0.1 - - [08/Jul/2025 10:29:59] "GET / HTTP/1.1" 200 -]
[2025-07-08 10:30:00,549: INFO : _internal : 127.0.0.1 - - [08/Jul/2025 10:30:00] "GET / HTTP/1.1" 200 -]
[2025-07-08 10:30:00,679: INFO : _internal : 127.0.0.1 - - [08/Jul/2025 10:30:00] "GET / HTTP/1.1" 200 -]
[2025-07-08 10:30:00,859: INFO : _internal : 127.0.0.1 - - [08/Jul/2025 10:30:00] "GET / HTTP/1.1" 200 -]
[2025-07-08 10:30:01,039: INFO : _internal : 127.0.0.1 - - [08/Jul/2025 10:30:01] "GET / HTTP/1.1" 200 -]
[2025-07-08 10:30:01,210: INFO : _internal : 127.0.0.1 - - [08/Jul/2025 10:30:01] "GET / HTTP/1.1" 200 -]
[2025-07-08 10:30:01,399: INFO : _internal : 127.0.0.1 - - [08/Jul/2025 10:30:01] "GET / HTTP/1.1" 200 -]
[2025-07-08 10:56:49,504: INFO : _internal : 127.0.0.1 - - [08/Jul/2025 10:56:49] "GET / HTTP/1.1" 200 -]
[2025-07-08 10:56:51,188: INFO : _internal : 127.0.0.1 - - [08/Jul/2025 10:56:51] "GET / HTTP/1.1" 200 -]
[2025-07-08 10:56:52,309: INFO : _internal : 127.0.0.1 - - [08/Jul/2025 10:56:52] "GET / HTTP/1.1" 200 -]
[2025-07-08 10:56:52,481: INFO : _internal : 127.0.0.1 - - [08/Jul/2025 10:56:52] "GET / HTTP/1.1" 200 -]
[2025-07-08 10:56:52,649: INFO : _internal : 127.0.0.1 - - [08/Jul/2025 10:56:52] "GET / HTTP/1.1" 200 -]
[2025-07-08 10:56:52,845: INFO : _internal : 127.0.0.1 - - [08/Jul/2025 10:56:52] "GET / HTTP/1.1" 200 -]
[2025-07-08 10:58:51,062: INFO : _internal : [31m[1mWARNING: This is a development server. Do not use it in a production deployment. Use a production WSGI server instead.[0m
 * Running on http://127.0.0.1:5000]
[2025-07-08 10:58:51,063: INFO : _internal : [33mPress CTRL+C to quit[0m]
[2025-07-08 10:58:51,076: INFO : _internal :  * Restarting with watchdog (inotify)]
[2025-07-08 10:58:51,926: WARNING : _internal :  * Debugger is active!]
[2025-07-08 10:58:51,927: INFO : _internal :  * Debugger PIN: 446-302-620]
[2025-07-08 10:58:57,621: INFO : _internal : 127.0.0.1 - - [08/Jul/2025 10:58:57] "GET / HTTP/1.1" 200 -]
[2025-07-08 11:01:14,105: INFO : _internal : 127.0.0.1 - - [08/Jul/2025 11:01:14] "GET / HTTP/1.1" 200 -]
[2025-07-08 11:31:47,393: INFO : _internal : 127.0.0.1 - - [08/Jul/2025 11:31:46] "GET / HTTP/1.1" 200 -]
[2025-07-08 11:31:52,567: INFO : _internal : 127.0.0.1 - - [08/Jul/2025 11:31:52] "GET / HTTP/1.1" 200 -]
[2025-07-08 11:33:16,384: INFO : _internal : 127.0.0.1 - - [08/Jul/2025 11:33:16] "GET / HTTP/1.1" 200 -]
[2025-07-08 11:33:35,024: INFO : _internal : 127.0.0.1 - - [08/Jul/2025 11:33:35] "GET / HTTP/1.1" 200 -]
[2025-07-08 11:34:01,429: INFO : _internal : 127.0.0.1 - - [08/Jul/2025 11:34:01] "GET / HTTP/1.1" 200 -]
[2025-07-08 11:34:03,683: INFO : _internal : 127.0.0.1 - - [08/Jul/2025 11:34:03] "GET / HTTP/1.1" 200 -]
[2025-07-08 11:35:20,017: INFO : _internal : 127.0.0.1 - - [08/Jul/2025 11:35:20] "GET / HTTP/1.1" 200 -]
[2025-07-08 11:46:06,276: INFO : _internal : 127.0.0.1 - - [08/Jul/2025 11:46:06] "GET / HTTP/1.1" 200 -]
[2025-07-08 11:49:35,715: INFO : _internal : 127.0.0.1 - - [08/Jul/2025 11:49:35] "GET / HTTP/1.1" 200 -]
[2025-07-08 12:00:56,704: INFO : _internal : 127.0.0.1 - - [08/Jul/2025 12:00:56] "GET / HTTP/1.1" 200 -]
[2025-07-08 12:00:57,702: INFO : _internal : 127.0.0.1 - - [08/Jul/2025 12:00:57] "[33mGET /static/images/static/images/red-wine-bottle-glass-table-vineyard-tuscany-italy-108313993.jpg HTTP/1.1[0m" 404 -]
[2025-07-08 12:01:00,867: INFO : _internal : 127.0.0.1 - - [08/Jul/2025 12:01:00] "GET / HTTP/1.1" 200 -]
[2025-07-08 12:01:01,195: INFO : _internal : 127.0.0.1 - - [08/Jul/2025 12:01:01] "[33mGET /static/images/static/images/red-wine-bottle-glass-table-vineyard-tuscany-italy-108313993.jpg HTTP/1.1[0m" 404 -]
[2025-07-08 12:04:16,319: INFO : _internal : 127.0.0.1 - - [08/Jul/2025 12:04:16] "GET / HTTP/1.1" 200 -]
[2025-07-08 12:04:16,396: INFO : _internal : 127.0.0.1 - - [08/Jul/2025 12:04:16] "[33mGET /static/images/red-wine-bottle-glass-table-vineyard-tuscany-italy-108313993.jpg HTTP/1.1[0m" 404 -]
[2025-07-08 12:04:18,005: INFO : _internal : 127.0.0.1 - - [08/Jul/2025 12:04:18] "GET / HTTP/1.1" 200 -]
[2025-07-08 12:04:18,086: INFO : _internal : 127.0.0.1 - - [08/Jul/2025 12:04:18] "[33mGET /static/images/red-wine-bottle-glass-table-vineyard-tuscany-italy-108313993.jpg HTTP/1.1[0m" 404 -]
[2025-07-08 12:04:19,252: INFO : _internal : 127.0.0.1 - - [08/Jul/2025 12:04:19] "GET / HTTP/1.1" 200 -]
[2025-07-08 12:04:19,316: INFO : _internal : 127.0.0.1 - - [08/Jul/2025 12:04:19] "[33mGET /static/images/red-wine-bottle-glass-table-vineyard-tuscany-italy-108313993.jpg HTTP/1.1[0m" 404 -]
[2025-07-08 12:04:19,551: INFO : _internal : 127.0.0.1 - - [08/Jul/2025 12:04:19] "GET / HTTP/1.1" 200 -]
[2025-07-08 12:04:19,626: INFO : _internal : 127.0.0.1 - - [08/Jul/2025 12:04:19] "[33mGET /static/images/red-wine-bottle-glass-table-vineyard-tuscany-italy-108313993.jpg HTTP/1.1[0m" 404 -]
[2025-07-08 12:04:19,755: INFO : _internal : 127.0.0.1 - - [08/Jul/2025 12:04:19] "GET / HTTP/1.1" 200 -]
[2025-07-08 12:04:19,878: INFO : _internal : 127.0.0.1 - - [08/Jul/2025 12:04:19] "[33mGET /static/images/red-wine-bottle-glass-table-vineyard-tuscany-italy-108313993.jpg HTTP/1.1[0m" 404 -]
[2025-07-08 12:04:19,919: INFO : _internal : 127.0.0.1 - - [08/Jul/2025 12:04:19] "GET / HTTP/1.1" 200 -]
[2025-07-08 12:04:19,952: INFO : _internal : 127.0.0.1 - - [08/Jul/2025 12:04:19] "[33mGET /static/images/red-wine-bottle-glass-table-vineyard-tuscany-italy-108313993.jpg HTTP/1.1[0m" 404 -]
[2025-07-08 12:05:16,556: INFO : _internal : 127.0.0.1 - - [08/Jul/2025 12:05:16] "GET / HTTP/1.1" 200 -]
[2025-07-08 12:05:16,643: INFO : _internal : 127.0.0.1 - - [08/Jul/2025 12:05:16] "[33mGET /static/images/red-wine-bottle-glass-table-vineyard-tuscany-italy-108313993.jpg HTTP/1.1[0m" 404 -]
[2025-07-08 12:23:55,047: INFO : _internal :  * Detected change in '/home/moses/Documents/machine_learning/End_to_end_ml_project/app.py', reloading]
[2025-07-08 12:23:55,048: INFO : _internal :  * Detected change in '/home/moses/Documents/machine_learning/End_to_end_ml_project/app.py', reloading]
[2025-07-08 12:23:55,171: INFO : _internal :  * Detected change in '/home/moses/Documents/machine_learning/End_to_end_ml_project/app.py', reloading]
[2025-07-08 12:24:08,445: INFO : _internal :  * Restarting with watchdog (inotify)]
[2025-07-08 12:27:47,211: INFO : _internal : [31m[1mWARNING: This is a development server. Do not use it in a production deployment. Use a production WSGI server instead.[0m
 * Running on http://127.0.0.1:5000]
[2025-07-08 12:27:47,212: INFO : _internal : [33mPress CTRL+C to quit[0m]
[2025-07-08 12:27:47,287: INFO : _internal :  * Restarting with watchdog (inotify)]
[2025-07-08 12:27:48,239: WARNING : _internal :  * Debugger is active!]
[2025-07-08 12:27:48,274: INFO : _internal :  * Debugger PIN: 446-302-620]
[2025-07-08 12:28:11,360: INFO : _internal : 127.0.0.1 - - [08/Jul/2025 12:28:11] "GET / HTTP/1.1" 200 -]
[2025-07-08 12:28:44,383: INFO : _internal : 127.0.0.1 - - [08/Jul/2025 12:28:44] "GET / HTTP/1.1" 200 -]
[2025-07-08 12:28:44,557: INFO : _internal : 127.0.0.1 - - [08/Jul/2025 12:28:44] "[33mGET /static/images/red-wine-bottle-glass-table-vineyard-tuscany-italy-108313993.jpg HTTP/1.1[0m" 404 -]
[2025-07-08 12:28:45,377: INFO : _internal : 127.0.0.1 - - [08/Jul/2025 12:28:45] "[33mGET /favicon.ico HTTP/1.1[0m" 404 -]
[2025-07-08 12:29:12,952: INFO : _internal : 127.0.0.1 - - [08/Jul/2025 12:29:12] "[33mPOST /predict HTTP/1.1[0m" 404 -]
[2025-07-08 12:29:30,157: INFO : _internal :  * Detected change in '/home/moses/Documents/machine_learning/End_to_end_ml_project/app.py', reloading]
[2025-07-08 12:29:30,161: INFO : _internal :  * Detected change in '/home/moses/Documents/machine_learning/End_to_end_ml_project/app.py', reloading]
[2025-07-08 12:29:30,240: INFO : _internal :  * Detected change in '/home/moses/Documents/machine_learning/End_to_end_ml_project/app.py', reloading]
[2025-07-08 12:29:30,861: INFO : _internal :  * Restarting with watchdog (inotify)]
[2025-07-08 12:29:38,242: WARNING : _internal :  * Debugger is active!]
[2025-07-08 12:29:38,243: INFO : _internal :  * Debugger PIN: 446-302-620]
[2025-07-08 12:29:57,950: INFO : _internal : [31m[1mWARNING: This is a development server. Do not use it in a production deployment. Use a production WSGI server instead.[0m
 * Running on http://127.0.0.1:5000]
[2025-07-08 12:29:57,950: INFO : _internal : [33mPress CTRL+C to quit[0m]
[2025-07-08 12:29:57,959: INFO : _internal :  * Restarting with watchdog (inotify)]
[2025-07-08 12:29:58,899: WARNING : _internal :  * Debugger is active!]
[2025-07-08 12:29:58,901: INFO : _internal :  * Debugger PIN: 446-302-620]
[2025-07-08 12:30:11,392: INFO : _internal : 127.0.0.1 - - [08/Jul/2025 12:30:11] "POST /predict HTTP/1.1" 200 -]
[2025-07-08 12:30:11,541: INFO : _internal : 127.0.0.1 - - [08/Jul/2025 12:30:11] "[33mGET /static/images/red-wine-bottle-glass-table-vineyard-tuscany-italy-108313993.jpg HTTP/1.1[0m" 404 -]
[2025-07-08 12:31:33,733: INFO : _internal : 127.0.0.1 - - [08/Jul/2025 12:31:33] "POST /predict HTTP/1.1" 200 -]
[2025-07-08 12:31:33,802: INFO : _internal : 127.0.0.1 - - [08/Jul/2025 12:31:33] "[33mGET /static/images/red-wine-bottle-glass-table-vineyard-tuscany-italy-108313993.jpg HTTP/1.1[0m" 404 -]
[2025-07-08 12:32:42,740: INFO : _internal : 127.0.0.1 - - [08/Jul/2025 12:32:42] "POST /predict HTTP/1.1" 200 -]
[2025-07-08 12:32:42,846: INFO : _internal : 127.0.0.1 - - [08/Jul/2025 12:32:42] "[33mGET /static/images/red-wine-bottle-glass-table-vineyard-tuscany-italy-108313993.jpg HTTP/1.1[0m" 404 -]
[2025-07-08 12:35:33,722: INFO : _internal : 127.0.0.1 - - [08/Jul/2025 12:35:33] "POST /predict HTTP/1.1" 200 -]
[2025-07-08 12:35:33,802: INFO : _internal : 127.0.0.1 - - [08/Jul/2025 12:35:33] "[33mGET /static/images/red-wine-bottle-glass-table-vineyard-tuscany-italy-108313993.jpg HTTP/1.1[0m" 404 -]
